{"e":"depthUpdate","E":1789582843230,"T":1789582843200,"s":"BTCUSDT","U":547193384217,"u":547193386552,"pu":547193383729,"b":[["75573.4","0.009"],["75835.0","1.773"],["75865.2","0.883"],["75891.9","0.132"],["75922.8","0.012"],["75934.2","0.002"],["75951.3","4.005"]],"a":[["75953.8","0.388"],["75965.0","4.144"],["76040.7","0.893"],["76044.2","0.018"],["76053.7","0.018"],["76071.0","1.803"],["76526.3","3.136"],["76668.1","0.089"]]}
{"e":"depthUpdate","E":1789582843331,"T":1789582843300,"s":"BTCUSDT","U":547193386658,"u":547193388787,"pu":547193386552,"b":[["75835.8","0.562"],["75866.8","0.283"],["75951.3","4.005"]],"a":[["75965.0","4.144"],["75980.5","0.002"],["76040.6","0.267"],["76053.6","0.008"],["76054.6","0.000"],["76064.3","0.011"],["76068.4","0.546"],["76267.5","0.000"]]}
{"e":"depthUpdate","E":1789582843481,"T":1789582843450,"s":"BTCUSDT","U":547193390028,"u":547193392285,"pu":547193388787,"b":[["73690.7","0.000"],["75943.8","1.189"],["75944.8","0.009"],["75944.9","0.009"],["75951.3","4.005"]],"a":[["75953.8","0.000"],["75953.9","0.000"],["75954.0","0.000"],["75957.1","0.000"],["75959.1","0.000"],["75965.0","2.894"],["75966.3","0.000"],["75968.5","0.000"],["75980.5","0.000"]]}
{"e":"depthUpdate","E":1789582843587,"T":1789582843550,"s":"BTCUSDT","U":547193392471,"u":547193394835,"pu":547193392285,"b":[["75946.8","0.000"],["75946.9","0.373"],["75951.3","4.005"],["75953.7","0.461"]],"a":[["75965.0","2.894"],["75966.5","0.688"],["75968.0","0.000"]]}
{"e":"depthUpdate","E":1789582843690,"T":1789582843650,"s":"BTCUSDT","U":547193394862,"u":547193397463,"pu":547193394835,"b":[["74964.7","0.000"],["75926.8","0.000"],["75934.2","0.000"],["75937.5","0.000"],["75939.0","0.000"],["75951.3","0.000"],["75953.7","0.331"],["75953.9","0.154"]],"a":[["75953.8","0.000"],["75958.7","0.000"],["75958.8","0.000"],["75958.9","0.000"],["75959.8","0.000"],["75961.9","0.000"],["75962.0","0.009"],["75964.6","0.000"],["75965.0","0.000"],["75966.5","0.370"],["75969.0","0.000"]]}
{"e":"depthUpdate","E":1789582843790,"T":1789582843750,"s":"BTCUSDT","U":547193397775,"u":547193400833,"pu":547193397463,"b":[["75116.7","0.000"],["75366.5","0.000"],["75478.9","0.000"],["75654.7","0.000"],["75897.3","0.000"],["75919.9","0.353"],["75930.5","0.003"],["75937.4","0.000"],["75939.2","0.003"],["75942.2","0.014"],["75946.9","0.000"],["75950.5","0.000"],["75951.3","0.000"],["75951.4","2.759"],["75952.9","0.000"],["75953.9","0.331"],["75954.0","0.620"],["75954.2","0.009"],["75954.3","0.009"],["75956.0","1.189"],["75958.6","0.000"],["75958.7","1.642"],["75958.8","0.036"]],"a":[["75962.0","0.000"],["75964.5","0.000"],["75965.0","0.000"],["75966.2","0.000"],["75966.4","0.000"],["75966.5","0.000"],["75966.6","0.000"],["75969.9","0.000"],["75971.2","0.000"],["75971.7","0.000"],["75972.5","0.000"],["75972.6","3.303"],["75972.7","0.000"],["75973.0","0.000"],["75974.5","0.000"],["75974.9","0.000"],["75976.1","0.000"],["75979.4","0.000"],["75980.8","0.000"],["75981.0","0.000"],["75981.1","0.000"],["75985.3","0.003"],["75987.3","0.000"],["75989.0","0.000"],["75990.0","1.766"],["76302.6","9.898"]]}
{"e":"depthUpdate","E":1789582843890,"T":1789582843850,"s":"BTCUSDT","U":547193400857,"u":547193404703,"pu":547193400833,"b":[["75922.8","0.009"],["75930.5","0.000"],["75938.9","0.360"],["75942.3","0.004"],["75945.5","0.026"],["75950.6","0.185"],["75951.4","1.189"],["75953.7","0.000"],["75953.8","0.922"],["75953.9","0.337"],["75955.5","0.013"],["75956.0","0.000"],["75956.1","0.355"],["75958.7","1.189"],["75958.8","0.508"],["75958.9","0.009"],["75959.0","0.009"],["75959.7","0.000"],["75961.8","0.000"],["75961.9","0.000"],["75964.9","0.122"],["75966.1","0.000"]],"a":[["75961.9","0.000"],["75965.4","1.189"],["75969.8","0.000"],["75971.6","0.000"],["75972.3","3.302"],["75972.4","9.874"],["75972.6","0.000"],["75976.4","0.176"],["75977.5","0.023"],["75979.1","0.023"],["75983.9","5.630"],["75984.9","0.495"],["75985.3","0.000"],["75987.5","0.026"],["75996.6","0.658"],["75999.1","0.441"],["76004.7","0.132"],["76006.9","0.074"],["76040.7","0.000"]]}
{"e":"depthUpdate","E":1789582843993,"T":1789582843950,"s":"BTCUSDT","U":547193404778,"u":547193408846,"pu":547193404703,"b":[["75546.1","0.063"],["75768.4","0.000"],["75897.4","0.004"],["75925.2","3.528"],["75936.9","0.176"],["75943.7","0.000"],["75950.6","0.000"],["75951.8","0.000"],["75953.1","0.002"],["75953.8","0.000"],["75954.0","1.015"],["75954.1","0.739"],["75956.1","0.004"],["75958.0","0.001"],["75958.8","0.514"],["75961.9","0.000"],["75964.9","0.000"],["75965.3","1.828"],["75966.1","0.000"],["75966.8","0.000"]],"a":[["75965.4","0.000"],["75972.3","13.176"],["75972.4","1.570"],["75974.4","0.051"],["75977.4","0.012"],["75978.0","0.013"],["75979.1","0.000"],["75982.6","2.002"],["75983.9","5.630"],["75988.9","0.490"],["75990.4","0.059"],["75999.3","0.002"],["76000.6","3.528"],["76004.3","0.061"],["76004.7","0.000"],["76016.3","0.059"],["76040.6","0.000"],["76076.1","0.173"]]}
{"e":"depthUpdate","E":1789582844093,"T":1789582844050,"s":"BTCUSDT","U":547193408909,"u":547193411237,"pu":547193408846,"b":[["75598.6","0.017"],["75927.7","1.390"],["75943.9","0.454"],["75954.0","0.620"],["75955.6","0.004"],["75956.1","0.000"],["75958.1","0.000"],["75958.4","0.000"],["75958.8","0.361"],["75964.9","0.000"],["75965.3","0.025"],["75966.5","0.130"],["75970.2","0.000"]],"a":[["75966.6","1.531"],["75967.8","1.189"],["75971.1","0.119"],["75972.2","3.906"],["75972.3","10.234"],["75972.4","1.210"],["75983.9","5.690"],["75990.0","1.898"],["76000.1","1.451"],["76004.3","0.022"],["76066.2","0.022"]]}
{"e":"depthUpdate","E":1789582844221,"T":1789582844200,"s":"BTCUSDT","U":547193411625,"u":547193414432,"pu":547193411237,"b":[["75835.0","0.000"],["75835.8","0.037"],["75919.2","0.000"],["75943.6","0.351"],["75955.5","0.000"],["75955.6","0.000"],["75958.7","0.000"],["75958.8","0.006"],["75965.3","0.000"],["75966.5","0.000"],["75966.6","0.000"]],"a":[["75966.6","0.342"],["75967.7","0.000"],["75971.1","0.000"],["75972.2","3.459"],["75974.1","0.013"],["75977.6","0.001"],["75978.0","0.000"],["75983.9","5.647"],["76055.2","0.947"]]}
{"e":"depthUpdate","E":1789582844323,"T":1789582844300,"s":"BTCUSDT","U":547193414792,"u":547193416830,"pu":547193414432,"b":[["75637.6","0.010"],["75877.9","0.976"],["75937.8","0.024"],["75938.9","0.848"],["75953.9","0.331"],["75954.1","0.744"],["75954.4","0.130"],["75958.8","0.000"],["75958.9","1.198"],["75959.0","0.340"],["75959.1","0.132"],["75960.8","0.130"],["75965.1","1.250"],["75966.5","0.000"]],"a":[["75966.5","0.457"],["75966.6","0.000"],["75967.8","0.000"],["75972.2","2.790"],["75974.1","0.000"],["75977.6","0.000"],["75983.9","5.632"],["75987.5","0.000"],["76053.6","0.290"],["76053.8","0.013"]]}
{"e":"depthUpdate","E":1789582844423,"T":1789582844400,"s":"BTCUSDT","U":547193416922,"u":547193419879,"pu":547193416830,"b":[["75870.6","0.037"],["75881.8","0.005"],["75904.8","0.003"],["75923.8","0.000"],["75938.9","0.000"],["75939.0","0.628"],["75943.6","0.000"],["75953.1","0.000"],["75953.9","0.000"],["75954.1","0.544"],["75954.4","0.000"],["75954.5","0.000"],["75955.7","0.013"],["75959.0","0.340"],["75959.1","0.461"],["75960.8","0.331"],["75960.9","0.002"],["75965.1","0.000"],["75965.2","0.130"],["75966.4","0.461"],["75966.5","0.000"]],"a":[["75966.5","0.000"],["75972.2","2.430"],["75972.3","0.000"],["75976.3","0.000"],["75983.9","5.630"],["75986.8","0.026"]]}
{"e":"depthUpdate","E":1789582844524,"T":1789582844500,"s":"BTCUSDT","U":547193420003,"u":547193422198,"pu":547193419879,"b":[["75870.5","0.000"],["75870.7","0.055"],["75939.0","0.420"],["75943.8","1.189"],["75954.4","0.395"],["75955.8","0.004"],["75959.0","0.009"],["75959.1","0.459"],["75959.6","0.000"],["75960.8","0.006"],["75965.2","0.000"],["75966.4","0.331"],["75966.5","0.331"],["75966.6","0.130"],["75970.2","2.165"]],"a":[["75972.2","0.703"],["75977.5","0.036"],["75983.9","5.630"],["76055.1","0.001"]]}
{"e":"depthUpdate","E":1789582844624,"T":1789582844600,"s":"BTCUSDT","U":547193422325,"u":547193424427,"pu":547193422198,"b":[["75870.1","0.032"],["75891.9","0.000"],["75944.7","0.000"],["75954.2","0.340"],["75954.4","0.000"],["75955.8","0.121"],["75959.1","0.000"],["75959.7","0.000"],["75963.3","1.250"],["75966.4","0.000"],["75966.5","0.130"],["75966.6","0.000"],["75970.2","2.165"],["75970.3","0.000"]],"a":[["75970.3","0.000"],["75972.1","0.124"],["75972.3","9.865"],["75983.9","5.630"]]}
{"e":"depthUpdate","E":1789582844726,"T":1789582844700,"s":"BTCUSDT","U":547193424631,"u":547193426328,"pu":547193424427,"b":[["75669.6","0.000"],["75907.2","0.132"],["75955.8","0.004"],["75963.3","0.000"],["75966.5","0.000"],["75970.2","2.165"],["75970.4","0.000"]],"a":[["75970.3","1.670"],["75972.3","9.747"],["75983.9","5.630"],["76002.6","0.003"]]}
{"e":"depthUpdate","E":1789582844828,"T":1789582844800,"s":"BTCUSDT","U":547193426587,"u":547193428390,"pu":547193426328,"b":[["72171.6","0.001"],["75945.1","0.003"],["75970.2","2.165"]],"a":[["75970.3","1.531"],["75972.1","0.000"],["75972.2","3.602"],["75983.9","5.630"],["75991.2","0.002"]]}
{"e":"depthUpdate","E":1789582844935,"T":1789582844900,"s":"BTCUSDT","U":547193429281,"u":547193431134,"pu":547193428390,"b":[["72171.6","0.000"],["75048.9","0.000"],["75395.2","0.000"],["75591.1","0.000"],["75711.7","0.000"],["75954.1","0.003"],["75954.3","0.296"],["75970.2","2.187"]],"a":[["75983.9","5.644"],["75991.2","0.000"],["76207.1","0.000"],["76328.5","0.000"],["76877.8","0.000"]]}
{"e":"depthUpdate","E":1789582845071,"T":1789582845000,"s":"BTCUSDT","U":547193431673,"u":547193433161,"pu":547193431134,"b":[["75954.3","0.614"],["75965.1","1.250"],["75970.2","2.191"]],"a":[["75983.9","5.650"],["76526.4","0.000"]]}
{"e":"depthUpdate","E":1789582845171,"T":1789582845150,"s":"BTCUSDT","U":547193433612,"u":547193435910,"pu":547193433161,"b":[["75600.6","31.506"],["75965.1","0.000"],["75970.2","2.165"]],"a":[["75983.9","5.630"]]}
{"e":"depthUpdate","E":1789582845272,"T":1789582845250,"s":"BTCUSDT","U":547193436061,"u":547193438179,"pu":547193435910,"b":[["75058.3","58.885"],["75404.6","42.035"],["75721.2","22.557"],["75967.7","0.000"],["75970.2","2.165"]],"a":[["75977.6","0.001"],["75983.9","5.630"],["75991.2","0.002"],["76215.7","21.879"],["76337.1","30.308"],["76535.0","40.800"],["76886.5","56.132"]]}
{"e":"depthUpdate","E":1789582845375,"T":1789582845350,"s":"BTCUSDT","U":547193438529,"u":547193440776,"pu":547193438179,"b":[["75871.9","0.016"],["75970.2","2.165"]],"a":[["75970.3","0.000"],["75972.3","0.000"],["75977.6","0.000"],["75983.9","5.630"]]}
{"e":"depthUpdate","E":1789582845475,"T":1789582845400,"s":"BTCUSDT","U":547193441008,"u":547193442553,"pu":547193440776,"b":[["75969.5","1.250"],["75970.2","2.165"],["75970.3","0.000"]],"a":[["75970.3","1.531"],["75972.1","9.877"],["75972.2","0.703"],["75983.9","5.630"]]}
{"e":"depthUpdate","E":1789582845579,"T":1789582845550,"s":"BTCUSDT","U":547193442948,"u":547193445351,"pu":547193442553,"b":[["75387.5","0.000"],["75969.5","0.000"],["75970.2","2.165"]],"a":[["75970.3","0.000"],["75972.0","3.309"],["75972.1","0.000"],["75972.2","0.000"],["75972.4","0.000"],["75983.9","5.630"]]}
{"e":"depthUpdate","E":1789582845680,"T":1789582845650,"s":"BTCUSDT","U":547193445389,"u":547193447688,"pu":547193445351,"b":[["75389.0","0.000"],["75901.2","0.005"],["75920.6","0.253"],["75963.3","1.250"],["75970.2","2.165"],["75970.3","0.130"]],"a":[["75972.0","0.000"],["75977.6","1.189"],["75983.9","5.630"]]}
{"e":"depthUpdate","E":1789582845780,"T":1789582845750,"s":"BTCUSDT","U":547193447707,"u":547193450201,"pu":547193447688,"b":[["75959.0","0.367"],["75963.3","0.000"],["75963.4","1.581"],["75970.2","2.165"],["75971.8","0.000"]],"a":[["75970.3","0.000"],["75971.8","0.444"],["75971.9","1.550"],["75973.6","9.747"],["75977.4","0.370"],["75983.9","5.630"],["76055.1","0.000"]]}
{"e":"depthUpdate","E":1789582845882,"T":1789582845850,"s":"BTCUSDT","U":547193450498,"u":547193452990,"pu":547193450201,"b":[["74553.0","0.000"],["75945.1","0.000"],["75955.8","0.000"],["75959.0","0.009"],["75963.4","0.000"],["75965.1","0.000"],["75970.2","2.165"],["75970.3","0.000"]],"a":[["75970.4","0.342"],["75971.8","0.000"],["75971.9","0.000"],["75973.5","2.962"],["75973.6","0.000"],["75974.3","0.655"],["75974.4","0.000"],["75976.4","0.000"],["75977.5","0.013"],["75977.6","0.001"],["75983.9","5.630"]]}
{"e":"depthUpdate","E":1789582845983,"T":1789582845950,"s":"BTCUSDT","U":547193453230,"u":547193455498,"pu":547193452990,"b":[["74557.8","0.001"],["74905.3","0.000"],["75884.5","0.000"],["75913.7","0.000"],["75935.9","0.037"],["75946.8","0.003"],["75954.0","0.000"],["75955.8","0.004"],["75959.0","0.367"],["75963.5","1.189"],["75970.2","2.182"],["75970.3","0.548"]],"a":[["75973.5","0.000"],["75974.3","0.000"],["75977.4","0.000"],["75977.5","0.000"],["75977.6","0.000"],["75979.2","0.000"],["75980.6","0.000"],["75983.9","4.394"],["75996.6","0.009"],["77446.9","0.000"],["77451.9","0.001"]]}
{"e":"depthUpdate","E":1789582846083,"T":1789582846050,"s":"BTCUSDT","U":547193455919,"u":547193459707,"pu":547193455498,"b":[["75511.5","0.000"],["75686.1","0.000"],["75884.6","0.000"],["75907.1","0.295"],["75916.4","0.003"],["75945.5","0.000"],["75951.5","0.019"],["75958.0","0.000"],["75963.4","1.250"],["75963.6","0.355"],["75968.4","0.009"],["75968.9","0.000"],["75970.2","0.000"],["75970.3","8.722"]],"a":[["75970.4","0.000"],["75979.1","0.000"],["75983.9","0.000"],["75984.9","0.494"],["75986.8","0.264"],["75990.0","1.000"],["75990.4","0.000"],["75991.2","0.000"],["75992.9","0.026"],["75994.4","0.195"],["75999.3","0.000"],["76055.1","0.001"]]}
{"e":"depthUpdate","E":1789582846183,"T":1789582846150,"s":"BTCUSDT","U":547193459711,"u":547193463682,"pu":547193459707,"b":[["75884.6","0.009"],["75908.8","0.244"],["75936.9","0.000"],["75951.5","0.000"],["75955.7","0.000"],["75958.9","0.009"],["75959.0","0.009"],["75961.0","0.001"],["75961.1","0.001"],["75961.4","0.000"],["75963.4","0.000"],["75963.5","0.000"],["75963.6","0.000"],["75968.4","0.000"],["75970.3","0.001"],["75970.4","0.000"],["75971.1","0.000"],["75973.1","0.000"],["75973.3","0.000"]],"a":[["75972.4","0.342"],["75974.0","1.189"],["75974.4","0.019"],["75981.8","0.000"],["75982.4","0.000"],["75982.5","0.000"],["75982.6","0.694"],["75986.0","0.176"],["75986.8","1.514"],["75987.8","1.213"],["75988.9","0.320"],["75994.4","0.327"],["75998.7","0.059"],["76001.6","0.002"],["76010.0","0.650"],["76099.0","0.109"]]}
{"e":"depthUpdate","E":1789582846283,"T":1789582846250,"s":"BTCUSDT","U":547193463709,"u":547193466741,"pu":547193463682,"b":[["75881.2","0.020"],["75907.2","0.000"],["75946.1","0.000"],["75946.8","0.000"],["75949.9","0.000"],["75951.4","0.000"],["75954.2","0.009"],["75955.8","0.000"],["75958.9","0.000"],["75959.0","0.000"],["75960.9","0.000"],["75961.0","0.000"],["75961.1","0.000"],["75970.2","0.000"],["75970.3","0.001"]],"a":[["75970.4","0.342"],["75971.2","0.124"],["75972.3","0.126"],["75973.9","0.000"],["75974.7","9.747"],["75980.5","0.001"],["75982.5","0.595"],["75983.9","0.000"],["75984.9","0.872"],["75986.0","0.000"],["75986.8","0.000"],["75987.8","1.212"],["75992.9","0.000"],["75997.0","0.650"],["76008.2","0.205"],["76010.0","0.000"],["76098.9","0.060"],["76099.9","0.000"]]}
{"e":"depthUpdate","E":1789582846384,"T":1789582846350,"s":"BTCUSDT","U":547193466883,"u":547193470646,"pu":547193466741,"b":[["75865.2","0.000"],["75871.0","0.017"],["75881.4","0.012"],["75896.1","0.132"],["75925.2","0.000"],["75937.5","0.176"],["75937.8","0.000"],["75939.1","0.691"],["75946.7","0.822"],["75948.6","0.002"],["75950.3","0.620"],["75954.1","0.000"],["75954.3","0.017"],["75954.4","1.520"],["75956.0","0.001"],["75956.3","0.000"],["75959.1","0.000"],["75960.8","0.000"],["75961.2","0.000"],["75963.4","0.000"],["75963.7","0.331"],["75964.6","0.000"],["75966.6","0.000"],["75968.4","0.000"],["75970.3","0.001"]],"a":[["75970.4","0.000"],["75971.1","0.019"],["75971.2","0.000"],["75972.2","1.189"],["75972.3","0.000"],["75972.4","0.000"],["75972.9","0.000"],["75973.8","9.747"],["75974.0","0.000"],["75974.4","0.000"],["75974.6","0.000"],["75974.7","0.000"],["75978.4","0.000"],["75979.1","0.009"],["75980.5","0.000"],["75980.7","0.009"],["75982.1","0.002"],["75982.4","0.000"],["75982.5","0.000"],["75982.6","0.342"],["75983.1","0.000"],["75983.9","0.000"],["75984.9","0.494"],["75987.7","0.000"],["75987.8","1.189"],["75989.7","0.214"],["75999.1","0.000"],["76008.2","0.013"]]}
{"e":"depthUpdate","E":1789582846484,"T":1789582846450,"s":"BTCUSDT","U":547193470673,"u":547193473724,"pu":547193470646,"b":[["75841.2","1.922"],["75866.8","0.017"],["75897.4","0.043"],["75927.7","0.387"],["75928.2","0.023"],["75937.5","0.000"],["75939.1","0.000"],["75943.9","0.000"],["75946.8","0.704"],["75948.6","0.000"],["75949.5","0.001"],["75950.4","0.185"],["75954.4","0.000"],["75956.0","0.000"],["75961.6","4.060"],["75963.7","0.000"],["75970.3","0.000"]],"a":[["75967.4","0.128"],["75970.4","1.689"],["75972.1","0.355"],["75972.3","0.600"],["75972.8","0.000"],["75973.7","2.909"],["75973.8","9.756"],["75973.9","0.009"],["75974.5","0.023"],["75975.3","6.760"],["75976.4","0.014"],["75976.8","1.189"],["75979.0","0.311"],["75980.6","0.093"],["75981.8","0.000"],["75982.0","0.130"],["75982.1","0.062"],["75982.4","0.000"],["75982.5","0.130"],["75982.6","0.342"],["75984.9","0.000"],["75994.0","0.003"],["75994.4","0.000"],["94964.5","0.001"],["94966.9","0.001"]]}
{"e":"depthUpdate","E":1789582846584,"T":1789582846550,"s":"BTCUSDT","U":547193473739,"u":547193475596,"pu":547193473724,"b":[["75601.5","0.018"],["75916.3","3.528"],["75937.8","0.026"],["75961.6","4.060"],["75963.8","0.130"],["75964.6","0.119"]],"a":[["75967.4","0.000"],["75970.4","1.531"],["75970.5","0.013"],["75972.1","0.000"],["75972.2","0.000"],["75972.3","0.000"],["75975.3","6.760"],["75979.0","0.135"],["75982.0","0.497"],["75982.5","0.000"],["75982.6","0.344"],["75984.9","0.361"]]}
{"e":"depthUpdate","E":1789582846686,"T":1789582846650,"s":"BTCUSDT","U":547193475740,"u":547193478734,"pu":547193475596,"b":[["75844.2","0.587"],["75875.6","0.016"],["75889.2","0.010"],["75916.4","1.055"],["75929.5","0.176"],["75931.6","0.017"],["75942.2","0.000"],["75947.9","0.013"],["75950.4","1.374"],["75950.6","0.001"],["75954.3","0.020"],["75954.5","0.331"],["75961.6","4.060"],["75963.8","0.000"]],"a":[["75963.8","0.000"],["75967.2","0.039"],["75967.3","0.000"],["75969.5","0.000"],["75970.3","1.080"],["75970.4","1.531"],["75973.7","4.937"],["75975.3","6.760"],["75976.3","0.001"],["75978.9","0.073"],["75979.0","0.000"],["75979.6","0.132"],["75980.3","0.026"],["75982.0","0.367"],["76002.6","0.000"]]}
{"e":"depthUpdate","E":1789582846788,"T":1789582846750,"s":"BTCUSDT","U":547193478799,"u":547193480951,"pu":547193478734,"b":[["74804.4","0.001"],["75931.6","0.068"],["75942.3","0.000"],["75944.5","0.002"],["75950.4","1.189"],["75950.5","0.544"],["75954.6","0.099"],["75961.6","2.810"]],"a":[["75964.7","1.531"],["75967.2","0.000"],["75970.3","0.643"],["75975.3","6.760"]]}
{"e":"depthUpdate","E":1789582846892,"T":1789582846850,"s":"BTCUSDT","U":547193481269,"u":547193483554,"pu":547193480951,"b":[["75937.3","1.191"],["75949.5","0.000"],["75954.6","0.000"],["75955.0","1.189"],["75957.7","1.250"],["75961.6","2.810"]],"a":[["75964.7","0.000"],["75967.1","0.000"],["75970.3","0.467"],["75975.3","5.510"],["75976.3","0.000"],["76162.3","0.000"]]}
{"e":"depthUpdate","E":1789582846997,"T":1789582846950,"s":"BTCUSDT","U":547193483960,"u":547193486233,"pu":547193483554,"b":[["75937.8","0.000"],["75942.2","0.014"],["75947.9","0.000"],["75950.6","0.000"],["75951.8","0.013"],["75952.5","0.001"],["75957.8","0.472"],["75961.6","0.036"],["75961.7","1.189"],["75964.6","6.702"]],"a":[["75964.7","0.342"],["75970.3","0.809"],["75970.5","0.000"],["75975.0","0.176"],["75975.3","0.000"],["75978.4","2.421"],["75979.4","0.001"],["75980.3","0.000"],["75982.1","0.000"],["75993.6","1.403"]]}
{"e":"depthUpdate","E":1789582847118,"T":1789582847050,"s":"BTCUSDT","U":547193486322,"u":547193488414,"pu":547193486233,"b":[["75941.9","0.026"],["75954.7","0.001"],["75957.7","1.250"],["75961.6","0.000"],["75961.7","0.000"],["75964.6","6.787"],["75964.7","0.000"]],"a":[["75965.8","0.000"],["75972.0","0.013"],["75973.7","2.909"],["75978.3","0.794"],["75978.4","2.420"],["75978.9","0.000"],["75981.7","0.026"],["75992.6","0.747"]]}
{"e":"depthUpdate","E":1789582847222,"T":1789582847200,"s":"BTCUSDT","U":547193488962,"u":547193490976,"pu":547193488414,"b":[["75942.3","0.005"],["75942.6","0.000"],["75954.3","0.015"],["75957.8","0.477"],["75964.6","6.770"]],"a":[["75978.4","2.418"],["75982.0","0.000"]]}
{"e":"depthUpdate","E":1789582847326,"T":1789582847300,"s":"BTCUSDT","U":547193491478,"u":547193493474,"pu":547193490976,"b":[["75942.3","0.012"],["75957.8","0.772"],["75964.6","6.701"]],"a":[["75964.7","0.000"],["75970.3","0.467"],["75970.4","0.000"],["75971.1","0.000"],["75972.0","0.000"],["75973.8","0.009"],["75978.4","1.168"],["75981.9","0.578"],["77120.5","0.000"]]}
{"e":"depthUpdate","E":1789582847427,"T":1789582847400,"s":"BTCUSDT","U":547193493557,"u":547193495826,"pu":547193493474,"b":[["75390.9","0.000"],["75590.1","0.016"],["75929.5","0.000"],["75959.0","0.009"],["75964.6","7.032"]],"a":[["75970.3","0.000"],["75973.7","0.000"],["75978.4","1.168"],["75980.1","0.000"]]}
{"e":"depthUpdate","E":1789582847528,"T":1789582847500,"s":"BTCUSDT","U":547193495864,"u":547193498299,"pu":547193495826,"b":[["75888.0","0.000"],["75928.2","0.000"],["75957.7","0.000"],["75959.1","0.012"],["75964.6","0.331"],["75964.7","7.832"],["75964.8","1.189"],["75970.2","0.000"]],"a":[["75970.2","0.000"],["75973.2","0.013"],["75976.4","0.000"],["75976.7","0.355"],["75978.3","0.421"],["75978.4","1.168"],["75978.9","1.250"],["75980.5","0.000"],["76033.3","0.010"],["76055.1","0.000"],["76057.3","0.001"],["88780.3","0.000"]]}
{"e":"depthUpdate","E":1789582847629,"T":1789582847600,"s":"BTCUSDT","U":547193498348,"u":547193501217,"pu":547193498299,"b":[["73700.4","0.000"],["74821.5","0.000"],["75051.1","0.000"],["75888.4","0.011"],["75896.1","0.000"],["75931.6","0.011"],["75940.5","0.023"],["75941.0","0.176"],["75941.9","0.000"],["75946.7","0.000"],["75950.6","0.019"],["75952.5","0.000"],["75954.3","0.009"],["75954.4","0.010"],["75957.8","0.477"],["75958.2","0.013"],["75959.1","0.009"],["75959.2","0.005"],["75964.6","0.000"],["75964.7","0.331"],["75964.8","1.195"],["75964.9","2.765"],["75967.3","0.001"],["75968.0","0.000"],["75970.1","7.064"],["75973.1","0.172"],["75973.7","0.471"]],"a":[["75973.2","0.000"],["75973.8","0.000"],["75973.9","0.000"],["75974.5","0.000"],["75975.0","0.000"],["75976.8","0.000"],["75978.3","0.741"],["75978.4","0.000"],["75978.9","0.000"],["75979.4","0.000"],["75979.6","0.000"],["75981.7","0.000"],["75983.8","3.002"],["75994.0","0.000"],["76000.6","0.000"]]}
{"e":"depthUpdate","E":1789582847767,"T":1789582847700,"s":"BTCUSDT","U":547193501253,"u":547193503469,"pu":547193501217,"b":[["75897.4","0.004"],["75909.6","0.132"],["75942.3","0.064"],["75946.8","0.460"],["75954.7","0.000"],["75957.9","0.001"],["75959.2","0.009"],["75964.9","0.489"],["75967.3","0.000"],["75970.1","8.165"],["75970.2","0.000"],["75973.1","0.000"],["75974.4","0.122"]],"a":[["75974.5","0.019"],["75976.6","1.189"],["75976.7","0.342"],["75978.3","0.033"],["75978.5","0.013"],["75981.9","1.291"],["75983.8","3.004"],["75984.8","0.001"],["75984.9","0.537"],["75985.9","0.024"],["75988.0","0.026"],["75989.9","0.132"],["76000.1","0.456"],["76002.5","0.003"],["76009.6","3.527"]]}
{"e":"depthUpdate","E":1789582847879,"T":1789582847850,"s":"BTCUSDT","U":547193503997,"u":547193506752,"pu":547193503469,"b":[["75937.3","1.189"],["75950.3","0.000"],["75959.4","0.001"],["75970.1","7.831"],["75973.7","0.331"],["75974.4","0.453"]],"a":[["75974.5","0.000"],["75976.5","0.355"],["75976.6","1.531"],["75978.5","0.000"],["75982.6","0.002"],["75983.8","1.750"],["75987.7","0.000"],["76008.2","1.064"],["76349.8","0.016"]]}
{"e":"depthUpdate","E":1789582847980,"T":1789582847950,"s":"BTCUSDT","U":547193506817,"u":547193509497,"pu":547193506752,"b":[["75940.5","0.000"],["75941.0","0.000"],["75950.5","0.355"],["75954.6","0.002"],["75962.9","0.620"],["75970.1","7.831"],["75972.7","0.001"],["75973.7","0.000"],["75974.4","0.000"],["75976.4","0.135"],["75976.5","0.000"]],"a":[["75974.5","0.000"],["75974.8","0.000"],["75976.5","0.342"],["75976.7","0.000"],["75981.9","0.815"],["75983.8","3.000"]]}
{"e":"depthUpdate","E":1789582848080,"T":1789582848050,"s":"BTCUSDT","U":547193509564,"u":547193511573,"pu":547193509497,"b":[["75780.8","0.018"],["75932.6","0.023"],["75933.6","0.176"],["75942.3","0.000"],["75942.4","0.021"],["75954.6","0.000"],["75970.1","7.831"],["75972.7","0.000"],["75976.4","0.000"]],"a":[["75977.5","0.013"],["75981.9","1.158"],["75983.8","3.000"],["75987.7","0.342"],["76228.1","0.010"]]}
{"e":"depthUpdate","E":1789582848183,"T":1789582848150,"s":"BTCUSDT","U":547193512125,"u":547193515036,"pu":547193511573,"b":[["75857.0","0.000"],["75878.3","0.000"],["75888.3","0.344"],["75932.9","0.000"],["75933.6","0.000"],["75933.7","0.158"],["75942.4","0.005"],["75948.8","0.003"],["75951.8","0.000"],["75954.5","0.333"],["75956.1","0.002"],["75957.4","0.014"],["75957.9","0.000"],["75958.2","0.000"],["75962.9","0.000"],["75963.2","1.250"],["75970.1","0.000"],["75970.2","4.279"],["75970.7","0.130"],["75971.0","0.009"],["75971.1","0.009"],["75974.8","0.009"],["75974.9","0.009"],["75976.4","4.034"]],"a":[["75976.5","0.000"],["75976.6","0.000"],["75977.5","0.000"],["75978.3","0.000"],["75979.1","0.000"],["75980.6","0.000"],["75980.7","0.000"],["75981.9","0.000"],["75982.6","0.000"],["75982.7","0.000"],["75982.9","0.000"],["75983.8","0.000"],["75984.8","0.000"],["75984.9","0.000"],["75985.9","0.000"],["75987.2","0.000"],["75987.7","0.000"],["75987.8","0.000"],["75988.0","0.000"],["75988.9","0.000"],["75989.7","0.000"],["75989.8","0.342"],["75989.9","0.000"],["75993.6","0.000"],["75997.0","0.000"],["76000.8","0.478"],["76001.6","0.000"],["76002.5","0.000"],["76003.5","0.000"],["76008.4","0.391"],["76022.9","0.301"],["76201.3","0.000"]]}
{"e":"depthUpdate","E":1789582848286,"T":1789582848250,"s":"BTCUSDT","U":547193515349,"u":547193518035,"pu":547193515036,"b":[["75227.6","0.020"],["75600.1","0.016"],["75677.9","0.016"],["75858.8","0.016"],["75878.4","3.248"],["75888.4","0.110"],["75906.3","0.000"],["75916.3","0.000"],["75932.6","0.000"],["75933.7","0.106"],["75944.5","0.000"],["75956.1","0.000"],["75957.8","0.472"],["75959.2","0.005"],["75959.4","0.000"],["75963.2","0.000"],["75964.9","0.766"],["75968.6","0.001"],["75970.1","0.000"],["75970.2","1.813"],["75970.3","1.277"],["75970.7","0.000"],["75976.4","0.331"],["75976.5","1.520"],["75977.4","1.650"]],"a":[["75984.8","0.003"],["75992.6","0.375"],["75994.4","0.417"],["75995.4","0.001"],["76002.0","0.035"],["76003.8","1.321"],["76016.9","0.650"],["76071.0","0.005"],["76526.3","0.000"],["76668.1","3.219"]]}
{"e":"depthUpdate","E":1789582848391,"T":1789582848350,"s":"BTCUSDT","U":547193518136,"u":547193521635,"pu":547193518035,"b":[["75897.7","0.012"],["75901.2","0.008"],["75908.8","0.117"],["75916.4","0.003"],["75921.6","11.465"],["75923.0","6.299"],["75939.2","0.000"],["75939.5","3.527"],["75949.5","0.023"],["75950.4","0.000"],["75950.6","0.000"],["75952.9","0.176"],["75954.5","0.002"],["75955.0","0.000"],["75958.6","0.026"],["75959.2","0.012"],["75964.7","0.000"],["75964.8","0.006"],["75964.9","0.489"],["75970.2","0.624"],["75970.3","0.000"],["75971.0","0.000"],["75971.1","0.000"],["75974.8","0.000"],["75974.9","0.000"],["75976.4","0.000"],["75976.5","1.189"],["75977.4","1.189"],["75980.7","6.580"],["75982.8","0.000"]],"a":[["75977.5","0.000"],["75979.2","0.000"],["75982.9","0.130"],["75983.2","0.126"],["75983.7","0.358"],["75983.8","1.189"],["75984.8","0.000"],["75985.1","0.343"],["75988.1","0.001"],["75988.4","0.000"],["75988.6","0.013"],["75989.0","0.176"],["75989.2","0.658"],["75989.3","1.189"],["75989.7","0.000"],["75989.8","0.000"],["75992.6","0.399"],["75994.4","1.667"],["75998.0","0.037"],["76002.0","0.009"],["76004.2","0.652"],["76009.5","0.003"],["76015.6","0.136"],["76016.9","0.000"],["76068.4","0.007"],["76395.8","0.127"]]}
{"e":"depthUpdate","E":1789582848491,"T":1789582848450,"s":"BTCUSDT","U":547193522176,"u":547193525029,"pu":547193521635,"b":[["75841.2","0.000"],["75909.6","0.000"],["75952.9","0.000"],["75954.4","0.061"],["75954.5","0.000"],["75957.4","0.000"],["75958.6","0.000"],["75964.9","0.000"],["75968.6","0.000"],["75970.2","0.000"],["75971.7","0.000"],["75976.5","0.000"],["75977.4","0.000"],["75980.7","0.000"]],"a":[["75982.0","0.062"],["75982.5","0.018"],["75982.6","0.026"],["75982.9","0.342"],["75983.2","0.000"],["75988.1","0.000"],["75988.6","0.000"],["75992.6","0.849"],["75994.4","0.000"],["75995.4","0.000"],["76008.4","0.000"],["76053.8","0.000"],["76055.2","0.000"],["94950.5","0.000"],["94964.5","0.000"]]}
{"e":"depthUpdate","E":1789582848591,"T":1789582848550,"s":"BTCUSDT","U":547193525278,"u":547193529687,"pu":547193525029,"b":[["75844.2","0.010"],["75889.6","0.912"],["75942.4","1.056"],["75949.6","0.008"],["75950.5","0.000"],["75953.7","0.002"],["75954.6","0.620"],["75955.1","1.189"],["75955.6","0.331"],["75957.8","0.005"],["75958.7","0.129"],["75959.3","0.129"],["75964.8","0.000"],["75964.9","0.129"],["75970.5","0.130"],["75970.8","0.000"]],"a":[["75970.3","0.000"],["75977.5","0.000"],["75977.8","0.000"],["75978.2","0.000"],["75978.7","0.000"],["75978.8","0.000"],["75979.1","0.000"],["75980.5","0.000"],["75980.8","0.000"],["75981.5","0.000"],["75981.9","0.000"],["75982.0","0.000"],["75982.1","0.000"],["75982.4","0.000"],["75982.5","0.000"],["75982.6","0.000"],["75982.7","0.000"],["75982.9","0.000"],["75983.1","0.000"],["75983.8","0.000"],["75984.5","0.000"],["75985.0","0.109"],["75985.1","0.001"],["75989.0","0.000"],["75992.6","0.825"],["75994.4","0.017"],["76003.2","0.003"],["76004.1","0.217"],["76004.3","0.000"],["76053.6","0.008"],["76063.7","0.910"],["76094.0","1.805"],["94952.1","0.001"],["94966.9","0.000"],["94975.3","0.003"],["94976.7","0.007"],["94978.8","0.003"]]}
{"e":"depthUpdate","E":1789582848691,"T":1789582848650,"s":"BTCUSDT","U":547193529705,"u":547193532906,"pu":547193529687,"b":[["75904.8","0.135"],["75940.4","0.000"],["75942.4","1.232"],["75948.0","0.000"],["75950.6","0.021"],["75954.4","0.004"],["75954.6","0.000"],["75955.6","0.331"],["75957.8","0.000"],["75957.9","1.722"],["75958.7","0.000"],["75959.2","0.005"],["75959.3","0.129"],["75960.2","1.189"],["75960.3","0.129"],["75960.6","0.129"],["75962.4","0.001"],["75964.8","0.331"],["75964.9","1.193"],["75965.0","0.013"],["75967.0","0.009"],["75967.2","0.009"],["75967.3","0.620"],["75970.5","0.331"],["75970.9","1.189"],["75971.7","0.000"],["75971.8","0.077"],["75974.6","5.415"],["75975.5","0.001"],["75977.4","0.452"],["75977.7","0.165"]],"a":[["75980.8","0.668"],["75982.8","1.189"],["75983.7","0.000"],["75984.5","0.000"],["75985.0","0.003"],["75988.3","0.505"],["75989.3","1.190"],["75992.6","0.375"],["75995.4","0.026"],["76058.7","0.013"]]}
{"e":"depthUpdate","E":1789582848792,"T":1789582848750,"s":"BTCUSDT","U":547193532988,"u":547193536321,"pu":547193532906,"b":[["75888.4","0.000"],["75889.7","0.387"],["75942.4","0.176"],["75942.6","0.000"],["75950.2","0.000"],["75953.7","0.000"],["75955.1","1.189"],["75955.6","0.331"],["75957.5","0.014"],["75957.9","0.000"],["75959.2","0.000"],["75959.3","0.000"],["75960.3","0.360"],["75960.6","0.000"],["75961.0","0.000"],["75962.4","0.000"],["75962.9","0.601"],["75963.3","0.000"],["75964.9","1.191"],["75965.0","0.000"],["75967.4","0.188"],["75970.5","0.004"],["75971.8","0.560"],["75974.6","0.000"],["75974.8","0.009"],["75975.5","0.000"],["75977.4","0.331"],["75977.5","1.189"],["75977.7","0.000"],["75977.8","0.184"],["75978.1","0.149"],["75978.7","0.129"],["75979.2","0.129"],["75980.7","0.121"]],"a":[["75979.5","0.000"],["75980.5","0.000"],["75980.8","0.000"],["75983.6","0.000"],["75983.7","0.342"],["75985.0","0.000"],["75985.4","0.013"],["75986.9","0.000"],["75988.3","0.000"],["75988.5","0.000"],["75989.3","0.000"],["75994.4","0.000"],["75995.4","0.000"],["75995.7","0.002"],["76003.2","0.000"],["76003.8","1.189"],["76009.5","0.000"],["76060.8","0.370"],["76068.2","0.000"],["76092.1","0.544"],["76303.3","0.005"],["76337.0","1.572"]]}
{"e":"depthUpdate","E":1789582848893,"T":1789582848850,"s":"BTCUSDT","U":547193536421,"u":547193539720,"pu":547193536321,"b":[["75904.8","0.003"],["75942.4","0.000"],["75942.7","1.057"],["75950.3","1.189"],["75955.7","0.461"],["75965.0","0.482"],["75968.9","0.001"],["75970.5","0.004"],["75971.2","0.000"],["75971.8","0.346"],["75972.3","1.250"],["75974.7","0.375"],["75975.0","0.009"],["75977.4","0.000"],["75977.7","0.000"],["75978.1","0.000"],["75978.7","0.000"],["75979.2","0.000"],["75979.4","6.911"],["75980.7","0.121"],["75982.7","0.160"]],"a":[["75983.7","0.000"],["75985.4","0.000"],["75988.2","0.155"],["75989.2","0.303"],["75989.3","0.176"],["75990.4","0.024"],["75994.8","1.549"],["75995.8","0.001"],["75995.9","0.000"],["76004.8","0.132"],["76010.0","0.641"],["76013.5","0.003"]]}
{"e":"depthUpdate","E":1789582848993,"T":1789582848950,"s":"BTCUSDT","U":547193539861,"u":547193543079,"pu":547193539720,"b":[["75741.5","0.000"],["75782.3","0.513"],["75920.0","0.132"],["75949.6","0.000"],["75950.4","0.363"],["75953.4","0.176"],["75954.4","0.011"],["75958.7","0.026"],["75968.7","0.013"],["75971.1","0.001"],["75972.3","0.000"],["75973.8","0.000"],["75974.7","0.000"],["75974.9","0.003"],["75975.1","0.005"],["75975.8","1.250"],["75978.1","0.000"],["75979.4","0.331"],["75980.7","0.335"],["75981.1","6.162"]],"a":[["75982.8","0.000"],["75988.2","0.000"],["75988.7","0.013"],["75989.1","1.189"],["75994.8","1.556"],["75998.5","0.026"],["76026.5","0.000"],["76047.8","0.353"],["76071.7","0.001"]]}
{"e":"depthUpdate","E":1789582849117,"T":1789582849050,"s":"BTCUSDT","U":547193543256,"u":547193546034,"pu":547193543079,"b":[["73115.6","0.000"],["73418.4","0.272"],["75818.0","0.000"],["75954.4","0.063"],["75974.9","0.000"],["75975.8","0.000"],["75979.4","0.000"],["75980.7","0.331"],["75981.1","7.480"],["75982.7","0.491"],["75983.7","0.001"],["75985.0","0.124"]],"a":[["75985.1","0.343"],["75988.6","0.250"],["75989.0","0.717"],["75989.2","0.000"],["75992.6","0.791"],["75994.8","0.305"],["75996.4","1.250"],["76013.0","0.002"],["76023.5","0.359"],["76045.8","0.108"],["76057.3","0.000"],["76071.7","0.000"]]}
{"e":"depthUpdate","E":1789582849228,"T":1789582849200,"s":"BTCUSDT","U":547193546523,"u":547193549588,"pu":547193546034,"b":[["75755.7","0.000"],["75820.6","0.013"],["75884.5","13.229"],["75920.6","0.000"],["75935.9","0.000"],["75958.7","0.000"],["75962.9","0.000"],["75967.3","0.000"],["75968.7","0.000"],["75968.9","0.000"],["75975.1","0.811"],["75977.8","0.331"],["75980.7","0.000"],["75981.1","0.000"],["75982.7","0.331"],["75983.7","0.000"],["75985.0","0.455"]],"a":[["75985.1","0.001"],["75988.5","0.000"],["75988.6","0.000"],["75988.7","0.000"],["75989.0","0.000"],["75989.1","0.000"],["75989.3","0.000"],["75990.4","0.000"],["75991.7","0.000"],["75992.6","0.000"],["75993.9","0.000"],["75994.3","0.000"],["75994.8","0.000"],["75995.6","0.000"],["75995.7","0.000"],["75995.8","0.000"],["75996.4","0.000"],["75996.6","0.000"],["75996.7","0.000"],["75997.6","0.000"],["75998.5","0.000"],["75998.7","0.000"],["76000.8","0.000"],["76004.2","0.002"],["76009.6","0.000"],["76010.6","0.000"],["76013.0","0.000"],["76013.5","0.000"],["76018.8","0.000"],["76042.6","0.342"],["76052.9","1.189"],["76071.0","0.000"],["76188.3","0.000"],["76244.1","0.000"],["76336.9","9.747"]]}
{"e":"depthUpdate","E":1789582849329,"T":1789582849300,"s":"BTCUSDT","U":547193549883,"u":547193552734,"pu":547193549588,"b":[["75565.3","0.000"],["75702.1","0.009"],["75941.3","0.251"],["75957.3","0.003"],["75959.0","0.046"],["75965.0","0.348"],["75965.5","0.026"],["75967.4","0.000"],["75975.1","0.806"],["75975.7","0.013"],["75976.5","0.001"],["75977.8","0.000"],["75978.1","1.250"],["75981.2","0.000"],["75982.7","0.331"],["75982.8","0.000"],["75983.1","0.009"],["75985.0","7.655"]],"a":[["75993.8","0.000"],["75997.3","1.237"],["75997.5","0.000"],["76002.4","4.485"],["76003.4","0.001"],["76004.1","0.000"],["76006.8","0.059"],["76007.1","0.026"],["76008.2","0.013"],["76016.8","0.211"],["76017.6","9.747"],["76020.3","3.527"],["76021.6","0.650"],["76031.3","0.059"],["76324.7","0.000"]]}
{"e":"depthUpdate","E":1789582849435,"T":1789582849400,"s":"BTCUSDT","U":547193553409,"u":547193556728,"pu":547193552734,"b":[["75757.9","0.575"],["75884.6","3.957"],["75948.8","0.000"],["75950.6","0.019"],["75967.4","0.005"],["75971.1","0.000"],["75975.2","0.246"],["75975.7","0.000"],["75978.2","0.728"],["75983.1","0.018"],["75985.0","6.738"]],"a":[["75985.1","0.343"],["75989.9","0.424"],["75992.7","1.189"],["75993.6","0.176"],["75995.9","0.013"],["75996.1","0.001"],["75997.2","0.571"],["75997.3","1.237"],["76000.1","1.644"],["76002.4","4.498"],["76004.1","0.063"],["76013.6","0.002"],["76058.7","0.000"],["76119.4","0.176"],["76364.7","0.009"]]}
