{"e":"depthUpdate","E":1788696020835,"T":1788696020833,"s":"BTCUSDT","ps":"BTCUSDT","U":11488689089390,"u":11488689095469,"pu":11488689089242,"b":[["29478.30","0.070"],["29578.30","1.813"],["29678.30","0.217"],["71890.40","0.002"],["76683.10","0.000"],["78680.10","9.010"],["78919.80","43.222"],["79079.50","10.589"],["79522.80","0.026"],["79524.80","0.040"]],"a":[["79892.40","0.190"],["79899.80","0.946"],["79900.60","0.004"],["79969.30","0.126"],["79969.70","0.000"],["79990.20","0.059"],["80517.40","3.469"],["80677.20","8.609"]],"st":1}
{"e":"depthUpdate","E":1788696020937,"T":1788696020936,"s":"BTCUSDT","ps":"BTCUSDT","U":11488689095568,"u":11488689103490,"pu":11488689095469,"b":[["29478.30","0.126"],["29578.30","1.876"],["29678.30","0.098"],["63903.00","0.000"],["71890.40","0.002"],["75884.50","0.267"],["76683.10","0.002"],["78520.40","10.030"],["78602.30","0.032"],["78603.30","0.000"],["78609.40","0.000"],["78612.40","0.003"],["78804.00","4.500"],["79079.50","10.589"],["79188.80","0.183"],["79239.30","7.216"],["79656.60","0.107"]],"a":[["79969.20","0.016"],["79969.30","0.001"],["80275.80","0.057"],["80637.20","5.108"],["80677.20","8.611"],["80837.60","6.326"]],"st":1}
{"e":"depthUpdate","E":1788696021039,"T":1788696021038,"s":"BTCUSDT","ps":"BTCUSDT","U":11488689103505,"u":11488689109662,"pu":11488689103490,"b":[["1000.00","24.604"],["29478.30","0.210"],["29578.30","1.890"],["29678.30","0.000"],["63903.00","0.000"],["71890.40","0.002"],["76683.10","0.000"],["79079.50","10.589"],["79118.80","0.631"],["79200.30","0.003"],["79478.90","4.470"],["79656.60","0.194"],["79657.80","0.001"],["79715.20","0.810"],["79754.70","0.179"],["79754.80","0.000"],["79808.60","0.855"],["79824.50","0.690"],["79859.20","0.266"],["79863.90","0.206"],["79868.50","0.094"],["79870.20","0.038"],["79878.30","12.627"]],"a":[["79886.10","0.028"],["79892.80","0.108"],["79897.80","0.438"],["79897.90","0.692"],["79898.00","0.004"],["79899.70","0.002"],["79914.30","0.002"],["79938.30","0.001"],["79990.20","0.059"],["80000.70","0.299"],["80040.20","1.516"],["80040.30","0.001"],["80088.10","7.460"],["80088.70","0.004"],["80277.80","4.148"],["80677.20","8.609"]],"st":1}
{"e":"depthUpdate","E":1788696021141,"T":1788696021137,"s":"BTCUSDT","ps":"BTCUSDT","U":11488689109772,"u":11488689118940,"pu":11488689109662,"b":[["29478.30","0.385"],["29578.30","1.715"],["63903.00","0.000"],["71890.40","0.002"],["76683.10","0.002"],["78989.60","1.264"],["79079.50","10.589"],["79522.80","0.026"],["79524.80","0.040"],["79656.60","0.194"],["79809.40","0.016"],["79812.10","20.710"],["79858.70","0.063"],["79859.50","0.003"],["79863.90","0.202"],["79875.60","0.040"]],"a":[["79892.40","0.190"],["79892.80","0.104"],["79897.80","0.503"],["79961.60","0.002"],["79990.20","0.070"],["80275.80","0.046"],["80677.20","8.609"],["80881.00","10.469"],["80996.70","37.946"]],"st":1}
{"e":"depthUpdate","E":1788696021243,"T":1788696021242,"s":"BTCUSDT","ps":"BTCUSDT","U":11488689119161,"u":11488689125813,"pu":11488689118940,"b":[["1000.00","24.754"],["29478.30","0.567"],["29578.30","1.533"],["71890.40","0.002"],["72928.90","0.259"],["73927.90","0.317"],["79079.50","10.589"],["79478.90","4.471"],["79656.60","0.194"],["79657.80","0.026"],["79715.20","0.000"],["79754.70","0.000"],["79804.00","24.165"],["79804.80","0.110"],["79808.60","0.029"],["79812.10","0.001"],["79824.50","0.001"],["79844.20","0.002"],["79844.90","2.305"],["79859.20","0.259"],["79859.60","0.315"],["79861.60","0.025"],["79868.50","0.098"],["79870.20","0.034"],["79875.60","0.040"],["79878.30","13.883"]],"a":[["79892.40","0.248"],["79897.60","0.022"],["79897.70","0.025"],["79897.80","0.065"],["79897.90","0.003"],["79898.00","0.002"],["79899.70","0.440"],["79899.80","0.945"],["79900.50","0.005"],["79914.30","0.000"],["79938.30","0.003"],["79969.90","0.000"],["79990.20","0.057"],["80000.70","0.030"],["80040.20","0.224"],["80275.80","0.001"],["80677.20","8.609"],["80758.90","0.693"],["80887.50","1.246"],["80950.00","12.842"],["81008.80","0.001"]],"st":1}
{"e":"depthUpdate","E":1788696021345,"T":1788696021341,"s":"BTCUSDT","ps":"BTCUSDT","U":11488689125874,"u":11488689134025,"pu":11488689125813,"b":[["1000.00","24.604"],["29478.30","0.742"],["29578.30","1.358"],["71890.40","0.002"],["76683.10","0.000"],["78440.50","8.271"],["79011.70","9.126"],["79079.50","10.589"],["79478.90","4.472"],["79522.80","0.026"],["79524.80","0.040"],["79656.60","0.174"],["79657.80","0.001"],["79715.20","1.313"],["79754.70","0.271"],["79804.00","24.165"],["79812.10","0.001"],["79860.00","0.013"],["79861.60","0.021"],["79875.60","0.040"],["79878.30","13.862"]],"a":[["79878.40","4.716"],["79883.80","0.133"],["79884.50","0.077"],["79892.40","0.250"],["79892.50","0.395"],["79896.00","2.404"],["79896.40","0.442"],["79897.90","0.001"],["79899.70","0.002"],["79969.40","0.038"],["79990.20","0.046"],["80000.70","0.349"],["80040.20","2.296"],["80115.80","0.000"],["80115.90","0.025"],["80277.80","4.147"],["80677.20","8.609"],["80836.90","32.464"],["81081.70","0.369"],["81243.60","0.492"]],"st":1}
{"e":"depthUpdate","E":1788696021447,"T":1788696021445,"s":"BTCUSDT","ps":"BTCUSDT","U":11488689134281,"u":11488689142746,"pu":11488689134025,"b":[["29478.30","0.924"],["29578.30","1.176"],["71890.40","0.002"],["76683.10","0.002"],["78656.20","4.581"],["78902.90","0.633"],["79007.60","3.414"],["79079.50","10.589"],["79656.60","0.107"],["79804.00","3.456"],["79809.40","20.725"],["79859.60","0.315"],["79875.60","0.040"]],"a":[["79892.40","0.192"],["79896.40","0.004"],["79899.60","0.283"],["79899.70","0.440"],["79990.20","0.057"],["80013.40","0.016"],["80082.80","0.000"],["80677.20","8.609"]],"st":1}
{"e":"depthUpdate","E":1788696021549,"T":1788696021546,"s":"BTCUSDT","ps":"BTCUSDT","U":11488689142900,"u":11488689150608,"pu":11488689142746,"b":[["1000.00","24.604"],["29478.30","1.099"],["29578.30","1.001"],["63902.60","0.000"],["71890.40","0.002"],["71927.00","0.033"],["76683.10","0.000"],["78873.20","11.663"],["79079.50","10.589"],["79478.90","4.462"],["79522.80","0.000"],["79524.80","0.000"],["79656.60","0.194"],["79657.80","0.013"],["79754.70","0.000"],["79858.60","0.134"],["79859.20","0.266"],["79859.50","0.002"],["79868.50","0.094"],["79870.20","0.038"],["79875.60","0.001"],["79878.20","0.022"],["79878.30","12.615"]],"a":[["79883.20","0.327"],["79888.40","0.006"],["79892.40","0.134"],["79894.90","0.001"],["79914.30","0.002"],["79938.30","0.001"],["80000.70","0.030"],["80639.00","1.362"],["80641.40","6.241"],["80677.20","8.609"],["80836.90","36.170"],["80910.10","5.679"],["81715.60","0.612"]],"st":1}
{"e":"depthUpdate","E":1788696021651,"T":1788696021650,"s":"BTCUSDT","ps":"BTCUSDT","U":11488689150781,"u":11488689158935,"pu":11488689150608,"b":[["1000.00","24.604"],["29478.30","1.281"],["29578.30","0.819"],["71890.40","0.002"],["71890.50","0.043"],["76683.10","0.002"],["78516.80","0.096"],["78744.00","2.880"],["79079.50","10.589"],["79239.30","4.067"],["79524.80","0.066"],["79656.60","0.107"],["79657.80","0.020"],["79715.20","1.319"],["79754.70","0.271"],["79809.40","0.016"],["79811.90","1.553"],["79812.10","20.710"],["79839.80","0.002"],["79859.20","0.704"],["79859.60","0.002"],["79859.90","0.000"],["79860.00","0.009"],["79860.60","0.000"],["79861.60","0.338"],["79861.90","0.565"],["79862.10","0.134"],["79862.90","0.000"],["79864.10","0.012"],["79875.60","0.001"]],"a":[["79878.40","4.703"],["79883.20","0.251"],["79884.50","0.001"],["79892.40","0.192"],["79895.90","0.439"],["79899.70","0.002"],["79901.90","0.574"],["79903.10","0.421"],["79904.10","1.656"],["79969.90","0.000"],["79990.20","0.001"],["80000.70","0.349"],["80040.10","0.564"],["80040.20","2.296"],["80040.40","0.001"],["80275.80","0.012"],["80677.20","8.609"],["80750.30","12.617"]],"st":1}
{"e":"depthUpdate","E":1788696021753,"T":1788696021752,"s":"BTCUSDT","ps":"BTCUSDT","U":11488689159024,"u":11488689167312,"pu":11488689158935,"b":[["29478.30","1.456"],["29578.30","0.644"],["71890.40","0.002"],["71890.50","0.041"],["78670.00","1.677"],["79011.70","8.558"],["79079.50","10.589"],["79600.00","13.479"],["79656.60","0.194"],["79657.80","0.001"],["79667.30","3.266"],["79778.50","0.003"],["79818.30","0.002"],["79859.20","0.259"],["79859.90","0.438"],["79860.00","0.322"],["79860.60","0.000"],["79861.60","0.021"],["79861.90","0.002"],["79862.00","0.002"],["79863.30","0.568"],["79868.50","0.098"],["79870.20","0.034"],["79878.30","13.866"]],"a":[["79882.90","0.014"],["79884.40","0.003"],["79892.40","0.250"],["79895.90","0.001"],["79896.00","2.404"],["79899.70","0.440"],["79901.90","0.011"],["79903.20","2.047"],["79914.30","0.000"],["79929.90","0.000"],["79938.30","0.003"],["79945.00","3.336"],["79946.90","0.000"],["79949.50","0.991"],["79949.60","0.002"],["79952.30","17.956"],["79963.20","0.003"],["79970.70","0.001"],["79990.20","0.046"],["80641.40","5.685"],["80677.20","8.609"],["80836.90","37.406"]],"st":1}
{"e":"depthUpdate","E":1788696021855,"T":1788696021853,"s":"BTCUSDT","ps":"BTCUSDT","U":11488689167375,"u":11488689175950,"pu":11488689167312,"b":[["1000.00","24.604"],["29478.30","1.638"],["29578.30","0.462"],["71890.40","0.002"],["75884.40","0.012"],["76683.10","0.000"],["78429.90","1.276"],["78879.80","11.933"],["79007.60","3.982"],["79079.50","10.589"],["79478.90","4.472"],["79522.80","0.026"],["79524.80","0.040"],["79656.60","0.174"],["79861.60","0.025"]],"a":[["79892.40","0.192"],["79903.20","1.484"],["79904.30","1.803"],["79945.00","0.692"],["79949.60","17.944"],["79952.30","0.014"],["79970.70","0.001"],["80275.80","0.001"],["80637.20","5.664"],["80677.20","8.610"],["81000.90","41.184"]],"st":1}
{"e":"depthUpdate","E":1788696021957,"T":1788696021953,"s":"BTCUSDT","ps":"BTCUSDT","U":11488689176123,"u":11488689183295,"pu":11488689175950,"b":[["1000.00","24.604"],["29378.30","0.021"],["29478.30","1.771"],["29578.30","0.308"],["71890.40","0.002"],["75884.40","0.014"],["76683.10","0.002"],["77635.20","1.032"],["78753.40","34.425"],["78879.80","12.148"],["78912.20","1.266"],["79079.50","10.589"],["79237.30","3.488"],["79656.60","0.194"],["79858.30","0.009"],["79878.20","0.024"],["79878.30","13.869"]],"a":[["79899.70","0.441"],["79900.50","0.004"],["79970.40","0.127"],["79970.70","0.001"],["79990.20","0.059"],["80275.80","0.057"],["80677.20","8.610"],["80876.90","9.554"],["80884.80","0.249"]],"st":1}
{"e":"depthUpdate","E":1788696022059,"T":1788696022055,"s":"BTCUSDT","ps":"BTCUSDT","U":11488689183532,"u":11488689191896,"pu":11488689183295,"b":[["29378.30","0.077"],["29478.30","1.834"],["29578.30","0.189"],["71890.40","0.002"],["75884.40","0.012"],["75884.50","0.269"],["76683.10","0.000"],["79079.50","10.589"],["79522.80","0.026"],["79524.80","0.040"],["79778.50","0.001"],["79818.30","0.004"],["79862.70","0.563"],["79863.30","0.005"],["79863.90","0.202"]],"a":[["79887.10","0.030"],["79892.40","0.192"],["79892.80","0.104"],["79896.60","0.080"],["79899.60","0.721"],["79899.70","0.003"],["79902.70","0.563"],["79902.80","0.003"],["79904.30","1.240"],["79925.50","0.411"],["79963.20","0.001"],["79970.40","0.002"],["80637.20","6.220"],["80677.20","8.610"],["80837.30","1.111"],["80956.80","6.193"],["82115.00","1.700"]],"st":1}
{"e":"depthUpdate","E":1788696022161,"T":1788696022160,"s":"BTCUSDT","ps":"BTCUSDT","U":11488689192175,"u":11488689204219,"pu":11488689191896,"b":[["1000.00","24.604"],["29378.30","0.140"],["29478.30","1.890"],["29578.30","0.070"],["71890.40","0.002"],["78843.90","11.463"],["78919.80","44.208"],["79079.50","10.591"],["79382.20","0.000"],["79478.90","4.472"],["79656.60","0.194"],["79657.80","0.001"],["79670.60","0.002"],["79808.50","0.839"],["79824.50","0.001"],["79846.30","0.033"],["79858.60","0.133"],["79859.70","0.028"],["79868.50","0.094"],["79869.50","0.003"],["79870.20","0.038"],["79878.30","12.618"]],"a":[["79879.40","0.000"],["79882.80","0.000"],["79883.40","0.251"],["79884.10","0.176"],["79897.80","0.503"],["79897.90","0.690"],["79898.00","0.004"],["79899.60","0.283"],["79914.30","0.002"],["79938.30","0.001"],["79946.90","17.942"],["79949.60","0.002"],["79990.20","0.115"],["80275.80","0.001"],["80677.20","8.610"],["80769.20","1.282"]],"st":1}
{"e":"depthUpdate","E":1788696022263,"T":1788696022262,"s":"BTCUSDT","ps":"BTCUSDT","U":11488689204226,"u":11488689213555,"pu":11488689204219,"b":[["1000.00","24.604"],["29378.30","0.252"],["29478.30","1.848"],["29578.30","0.000"],["71890.40","0.002"],["76683.10","0.002"],["79079.50","10.589"],["79478.90","4.471"],["79656.30","2.559"],["79656.60","0.194"],["79667.30","3.311"],["79740.30","2.549"],["79824.40","2.549"],["79837.00","2.368"],["79848.40","1.095"],["79858.90","0.001"],["79859.20","0.266"],["79859.70","0.027"],["79869.80","0.041"]],"a":[["79878.40","4.702"],["79883.30","0.006"],["79892.40","0.250"],["79897.90","0.692"],["79899.80","1.551"],["79923.70","3.252"],["79931.90","0.015"],["79940.70","1.374"],["79946.90","0.000"],["79952.30","17.956"],["79970.30","2.588"],["79990.20","0.057"],["80089.90","2.986"],["80277.80","4.148"],["80677.20","8.610"],["82191.50","0.000"]],"st":1}
{"e":"depthUpdate","E":1788696022365,"T":1788696022364,"s":"BTCUSDT","ps":"BTCUSDT","U":11488689213709,"u":11488689222293,"pu":11488689213555,"b":[["29378.30","0.427"],["29478.30","1.673"],["63903.00","0.000"],["71890.40","0.002"],["72729.10","0.256"],["73728.10","0.317"],["76683.10","0.000"],["77977.80","0.106"],["78724.10","33.116"],["79003.70","2.349"],["79079.50","10.589"],["79478.90","4.470"],["79522.80","0.030"],["79524.80","0.036"],["79656.60","0.174"],["79659.50","0.970"],["79661.00","0.012"],["79668.60","0.033"],["79804.00","24.229"],["79812.10","0.001"],["79836.90","1.387"],["79859.20","0.259"],["79868.50","0.098"],["79870.20","0.034"],["79878.30","13.869"]],"a":[["79878.40","4.699"],["79886.40","0.516"],["79892.40","0.209"],["79897.70","0.025"],["79897.80","0.065"],["79897.90","0.003"],["79898.00","0.002"],["79899.70","0.440"],["79900.60","0.005"],["79914.30","0.000"],["79920.20","0.969"],["79938.30","0.003"],["79949.60","17.944"],["79952.30","0.014"],["79969.90","0.000"],["79990.20","0.057"],["80088.00","2.677"],["80277.80","4.149"],["80517.40","2.726"],["80677.20","8.610"],["80761.20","8.470"],["80910.20","2.602"],["81080.70","21.482"]],"st":1}
{"e":"depthUpdate","E":1788696022467,"T":1788696022465,"s":"BTCUSDT","ps":"BTCUSDT","U":11488689222315,"u":11488689229884,"pu":11488689222293,"b":[["1000.00","24.604"],["29378.30","0.609"],["29478.30","1.491"],["71890.40","0.002"],["76683.10","0.002"],["78512.70","0.636"],["78839.90","8.548"],["78919.80","45.220"],["79079.50","10.589"],["79478.90","4.460"],["79656.60","0.000"],["79668.60","0.207"],["79754.70","0.268"],["79804.00","3.456"],["79809.40","20.789"],["79824.70","0.001"],["79854.30","0.014"],["79859.60","0.002"],["79862.10","0.697"],["79862.70","0.000"],["79878.30","13.869"]],"a":[["79878.50","0.282"],["79885.70","0.001"],["79892.40","0.209"],["79894.90","0.077"],["79896.00","2.842"],["79897.60","0.022"],["79897.90","0.001"],["79899.60","0.283"],["79899.70","0.002"],["79902.40","0.624"],["79938.40","0.002"],["79990.20","0.057"],["80000.60","0.320"],["80000.70","0.030"],["80677.20","8.610"],["81019.30","0.148"]],"st":1}
{"e":"depthUpdate","E":1788696022569,"T":1788696022567,"s":"BTCUSDT","ps":"BTCUSDT","U":11488689230029,"u":11488689238246,"pu":11488689229884,"b":[["1000.00","24.604"],["29378.30","0.784"],["29478.30","1.316"],["63902.60","0.000"],["71890.40","0.002"],["71927.00","0.033"],["75881.70","0.000"],["76683.10","0.000"],["77881.30","1.477"],["78799.90","5.570"],["78999.60","5.437"],["79079.50","10.589"],["79522.80","0.030"],["79524.80","0.036"],["79667.20","5.078"],["79667.30","0.211"],["79824.70","0.002"],["79854.40","0.482"],["79855.30","0.453"],["79861.80","0.191"],["79862.20","0.074"],["79875.60","0.040"]],"a":[["79880.70","0.152"],["79882.20","0.005"],["79883.80","0.131"],["79883.90","0.164"],["79885.80","0.076"],["79886.40","0.591"],["79892.20","0.062"],["79892.40","0.072"],["79896.00","2.404"],["79899.70","0.440"],["79902.70","0.000"],["79902.80","0.001"],["79903.30","0.566"],["79938.40","0.003"],["80517.40","3.469"],["80677.20","9.848"],["80757.10","5.148"],["81076.60","7.650"]],"st":1}
{"e":"depthUpdate","E":1788696022671,"T":1788696022669,"s":"BTCUSDT","ps":"BTCUSDT","U":11488689238417,"u":11488689245161,"pu":11488689238246,"b":[["29378.30","0.966"],["29478.30","1.134"],["63903.00","0.000"],["71890.40","0.002"],["79079.50","10.589"],["79239.30","4.318"],["79667.20","5.135"],["79668.60","0.120"],["79811.90","4.511"],["79859.20","0.266"],["79861.90","0.064"],["79862.20","0.012"],["79868.50","0.094"],["79870.20","0.038"],["79875.60","0.040"],["79878.10","0.156"],["79878.30","12.617"]],"a":[["79882.30","0.000"],["79892.40","0.059"],["79914.30","0.002"],["79938.30","0.001"],["79970.00","0.053"],["79990.20","0.012"],["80517.40","3.716"],["80677.20","9.848"],["80812.80","0.001"]],"st":1}
{"e":"depthUpdate","E":1788696022773,"T":1788696022772,"s":"BTCUSDT","ps":"BTCUSDT","U":11488689245353,"u":11488689252183,"pu":11488689245161,"b":[["1000.00","24.604"],["29378.30","1.141"],["29478.30","0.959"],["63903.00","0.000"],["71890.40","0.002"],["75884.40","0.010"],["75884.50","0.271"],["76683.10","0.002"],["78832.30","1.268"],["79079.50","10.589"],["79159.40","12.218"],["79478.90","4.470"],["79522.80","0.000"],["79524.80","0.000"],["79667.20","3.055"],["79668.60","0.207"],["79853.60","0.452"],["79855.30","0.003"],["79858.60","0.134"],["79858.90","0.000"],["79875.60","0.040"]],"a":[["79886.40","0.475"],["79892.40","0.072"],["79896.00","2.404"],["79899.70","0.440"],["79903.90","0.172"],["79905.50","0.450"],["79931.90","0.001"],["79940.80","3.552"],["79969.60","0.000"],["79969.90","0.125"],["79970.10","0.000"],["80677.20","9.848"],["80876.90","10.480"]],"st":1}
{"e":"depthUpdate","E":1788696022875,"T":1788696022873,"s":"BTCUSDT","ps":"BTCUSDT","U":11488689252227,"u":11488689257540,"pu":11488689252183,"b":[["1000.00","24.604"],["29378.30","1.323"],["29478.30","0.777"],["71890.40","0.002"],["76683.10","0.000"],["78919.80","41.424"],["79079.50","10.589"],["79239.30","4.318"],["79524.80","0.066"],["79667.20","5.129"],["79668.60","0.120"],["79808.50","0.013"],["79859.20","0.259"],["79868.50","0.098"],["79870.20","0.034"],["79875.60","0.040"],["79878.30","13.924"]],"a":[["79878.40","4.692"],["79882.20","0.003"],["79886.40","0.591"],["79899.50","0.007"],["79900.60","0.004"],["79914.30","0.000"],["79938.30","0.003"],["79969.80","0.038"],["79969.90","0.000"],["79990.20","0.012"],["80677.20","9.847"],["80841.10","30.954"],["80877.50","5.508"],["80965.90","3.955"]],"st":1}
{"e":"depthUpdate","E":1788696022977,"T":1788696022974,"s":"BTCUSDT","ps":"BTCUSDT","U":11488689257755,"u":11488689264944,"pu":11488689257540,"b":[["29378.30","1.498"],["29478.30","0.602"],["63903.00","0.002"],["71890.40","0.002"],["76683.10","0.002"],["79079.50","10.589"],["79667.20","3.056"],["79668.60","0.207"],["79800.00","15.018"],["79858.10","0.129"],["79858.40","0.008"],["79859.10","0.827"],["79860.00","0.322"],["79861.60","0.025"],["79875.60","0.040"]],"a":[["79883.40","0.000"],["79885.80","0.000"],["79886.10","0.002"],["79886.30","0.017"],["79892.40","0.068"],["79892.50","0.389"],["79896.40","0.004"],["79899.50","0.006"],["79899.70","0.440"],["79900.50","0.005"],["79932.00","0.018"],["79940.80","3.538"],["79969.20","0.016"],["79990.20","0.057"],["80677.20","9.847"],["80769.00","0.185"],["80956.80","6.685"],["81004.70","2.466"]],"st":1}
{"e":"depthUpdate","E":1788696023079,"T":1788696023078,"s":"BTCUSDT","ps":"BTCUSDT","U":11488689265166,"u":11488689274141,"pu":11488689264944,"b":[["1000.00","24.604"],["29378.30","1.673"],["29478.30","0.427"],["63903.00","0.000"],["71890.40","0.002"],["76683.10","0.000"],["77378.80","0.118"],["78378.00","2.991"],["78919.80","45.220"],["79079.50","10.589"],["79478.90","4.470"],["79524.80","0.066"],["79668.60","0.187"],["79863.90","0.202"],["79875.60","0.001"],["79878.30","13.924"]],"a":[["79883.70","0.251"],["79885.80","0.076"],["79886.30","0.007"],["79886.40","0.594"],["79888.40","0.009"],["79888.60","0.415"],["79892.20","0.072"],["79892.40","0.065"],["79892.80","0.104"],["79896.40","0.442"],["79899.70","0.002"],["79969.70","0.000"],["79990.20","0.046"],["80677.20","9.847"],["80877.70","1.234"]],"st":1}
{"e":"depthUpdate","E":1788696023181,"T":1788696023178,"s":"BTCUSDT","ps":"BTCUSDT","U":11488689274215,"u":11488689280806,"pu":11488689274141,"b":[["1000.00","24.604"],["29378.30","1.785"],["29478.30","0.280"],["29778.30","0.035"],["63903.00","0.000"],["71890.40","0.002"],["79079.50","10.589"],["79382.20","0.000"],["79667.20","3.056"],["79668.60","0.207"],["79780.80","0.002"],["79834.50","0.892"],["79850.50","1.260"],["79878.10","0.194"],["79878.30","13.929"]],"a":[["79892.40","0.065"],["79896.40","0.004"],["79897.80","0.503"],["79897.90","0.690"],["79898.00","0.004"],["79899.70","0.002"],["79956.00","0.002"],["79956.10","0.034"],["79961.60","0.001"],["79962.00","3.761"],["79990.20","0.057"],["80677.20","9.847"]],"st":1}
{"e":"depthUpdate","E":1788696023283,"T":1788696023281,"s":"BTCUSDT","ps":"BTCUSDT","U":11488689281072,"u":11488689289225,"pu":11488689280806,"b":[["29378.30","1.841"],["29478.30","0.161"],["29778.30","0.098"],["71890.40","0.002"],["76683.10","0.002"],["78873.20","11.511"],["78873.30","0.304"],["79079.50","10.589"],["79522.80","0.026"],["79524.80","0.040"],["79754.70","0.268"],["79784.10","0.134"],["79834.50","0.066"],["79850.50","0.571"],["79853.60","0.002"],["79855.30","0.453"],["79859.20","0.266"],["79861.90","0.002"],["79862.20","0.074"],["79868.50","0.094"],["79870.20","0.038"],["79878.30","12.677"]],"a":[["79880.70","0.000"],["79881.30","0.155"],["79883.80","0.129"],["79883.90","0.162"],["79884.00","0.012"],["79884.50","0.077"],["79886.40","0.594"],["79897.90","0.692"],["80000.60","0.320"],["80277.80","4.148"],["80597.70","1.262"],["80639.00","0.000"],["80677.20","9.847"],["80917.80","0.864"],["81005.90","1.039"]],"st":1}
{"e":"depthUpdate","E":1788696023385,"T":1788696023383,"s":"BTCUSDT","ps":"BTCUSDT","U":11488689289463,"u":11488689296025,"pu":11488689289225,"b":[["1000.00","24.604"],["29378.30","1.904"],["29478.30","0.042"],["29778.30","0.154"],["71890.40","0.002"],["76683.10","0.000"],["78872.30","0.633"],["79079.50","10.589"],["79239.30","4.067"],["79478.90","4.462"],["79668.60","0.120"],["79784.10","0.009"],["79855.10","0.652"],["79855.30","0.003"],["79856.30","0.000"],["79857.70","0.006"],["79858.40","0.002"],["79859.90","0.000"],["79860.00","0.009"],["79860.60","0.438"],["79861.60","0.025"],["79861.70","0.447"],["79862.00","0.064"],["79862.10","0.134"],["79862.20","0.012"],["79862.90","0.563"],["79864.10","0.012"]],"a":[["79886.20","0.031"],["79892.40","0.007"],["79897.80","0.503"],["79899.70","0.002"],["79903.30","0.003"],["79904.10","2.219"],["79905.50","0.000"],["79905.90","0.450"],["79907.70","0.006"],["79908.70","0.014"],["79969.60","0.125"],["79990.20","0.057"],["80277.80","4.147"],["80677.20","9.847"],["80758.00","0.185"]],"st":1}
{"e":"depthUpdate","E":1788696023487,"T":1788696023485,"s":"BTCUSDT","ps":"BTCUSDT","U":11488689296282,"u":11488689303083,"pu":11488689296025,"b":[["1000.00","24.604"],["29378.30","1.806"],["29478.30","0.000"],["29778.30","0.294"],["71890.40","0.002"],["72529.30","0.256"],["73528.30","0.317"],["76683.10","0.002"],["78598.30","0.003"],["78602.30","0.030"],["79079.50","10.589"],["79668.60","0.207"],["79858.60","0.133"],["79859.20","0.259"],["79859.50","0.003"],["79859.60","0.002"],["79868.50","0.098"],["79870.20","0.034"],["79878.30","13.928"]],"a":[["79878.40","4.691"],["79883.30","0.005"],["79884.50","0.001"],["79892.40","0.065"],["79897.60","0.460"],["79897.70","0.025"],["79897.80","0.065"],["79897.90","0.003"],["79898.00","0.002"],["79899.60","0.283"],["79899.70","0.002"],["79969.60","0.000"],["80677.20","9.847"],["83872.30","0.011"]],"st":1}
{"e":"depthUpdate","E":1788696023589,"T":1788696023588,"s":"BTCUSDT","ps":"BTCUSDT","U":11488689303271,"u":11488689309039,"pu":11488689303083,"b":[["29378.30","1.631"],["29778.30","0.469"],["63902.60","0.000"],["71890.40","0.002"],["71927.00","0.036"],["78564.30","0.154"],["78872.30","0.000"],["78909.70","1.272"],["79079.50","10.589"],["79522.80","0.026"],["79524.80","0.040"],["79668.60","0.207"],["79694.60","0.001"],["79694.70","3.130"],["79792.50","0.261"],["79792.80","0.003"],["79862.60","0.001"],["79865.80","0.012"]],"a":[["79886.40","0.478"],["79891.30","0.291"],["79892.40","0.181"],["79894.50","0.004"],["79897.20","0.447"],["79897.30","0.005"],["79897.40","0.001"],["79897.50","0.004"],["79897.60","0.022"],["79899.70","0.002"],["79968.30","0.039"],["79968.60","0.005"],["79990.20","0.057"],["80019.30","3.130"],["80019.50","0.000"],["80677.20","9.847"],["80996.70","39.796"]],"st":1}
{"e":"depthUpdate","E":1788696023691,"T":1788696023689,"s":"BTCUSDT","ps":"BTCUSDT","U":11488689309118,"u":11488689315901,"pu":11488689309039,"b":[["1000.00","24.604"],["29378.30","1.449"],["29778.30","0.651"],["63903.00","0.000"],["71890.40","0.002"],["71927.00","0.033"],["76683.10","0.000"],["77641.70","1.298"],["78560.30","5.276"],["78753.40","34.172"],["79079.50","10.589"],["79478.90","4.472"],["79667.20","3.056"],["79668.60","0.207"],["79715.20","1.301"],["79754.70","0.268"]],"a":[["79892.40","0.181"],["79897.20","0.009"],["79897.90","0.001"],["79899.70","0.441"],["79900.50","0.004"],["79949.50","3.577"],["79990.20","0.012"],["80000.60","0.320"],["80040.00","0.682"],["80040.10","2.072"],["80040.20","0.224"],["80088.10","7.459"],["80275.80","0.046"],["80677.20","9.847"]],"st":1}
{"e":"depthUpdate","E":1788696023793,"T":1788696023792,"s":"BTCUSDT","ps":"BTCUSDT","U":11488689316006,"u":11488689324541,"pu":11488689315901,"b":[["1000.00","24.604"],["29378.30","1.274"],["29778.30","0.826"],["71890.40","0.002"],["76683.10","0.002"],["76713.60","0.133"],["79079.50","10.589"],["79522.80","0.000"],["79524.80","0.066"],["79668.60","0.187"],["79754.70","0.000"],["79784.60","0.015"],["79784.70","0.000"],["79804.80","0.098"],["79859.20","0.266"],["79862.60","0.472"],["79865.80","0.364"],["79868.50","0.094"],["79870.20","0.038"],["79878.30","12.677"]],"a":[["79878.40","4.641"],["79883.60","0.004"],["79886.40","0.509"],["79892.40","0.150"],["79969.60","0.000"],["79969.70","0.000"],["79969.90","0.000"],["79990.20","0.001"],["80000.60","0.001"],["80277.80","4.023"],["80677.20","9.847"],["80853.20","0.975"],["81000.90","39.335"]],"st":1}
{"e":"depthUpdate","E":1788696023895,"T":1788696023893,"s":"BTCUSDT","ps":"BTCUSDT","U":11488689324643,"u":11488689333834,"pu":11488689324541,"b":[["29378.30","1.092"],["29778.30","1.008"],["63903.00","0.000"],["71890.40","0.002"],["76683.10","0.000"],["78756.90","0.381"],["79079.50","10.589"],["79668.60","0.120"],["79784.50","0.000"],["79784.70","0.125"],["79838.30","0.008"],["79853.60","0.452"],["79855.10","0.202"],["79858.70","0.064"],["79859.50","0.002"],["79862.00","0.627"],["79862.30","0.198"],["79862.90","0.000"]],"a":[["79892.40","0.092"],["79894.40","0.951"],["79902.00","0.770"],["79904.10","1.656"],["79907.70","0.000"],["79908.70","0.020"],["79918.40","0.274"],["79969.60","0.000"],["79990.20","0.057"],["80275.80","0.001"],["80277.80","4.147"],["80677.20","9.847"],["83872.30","0.015"]],"st":1}
{"e":"depthUpdate","E":1788696023997,"T":1788696023996,"s":"BTCUSDT","ps":"BTCUSDT","U":11488689333932,"u":11488689342664,"pu":11488689333834,"b":[["1000.00","24.604"],["29378.30","0.917"],["29778.30","1.183"],["63903.00","0.002"],["71890.40","0.002"],["76683.10","0.002"],["78644.20","14.320"],["78919.80","44.588"],["79079.50","10.589"],["79478.90","4.472"],["79524.80","0.000"],["79664.20","0.027"],["79667.20","5.130"],["79667.90","1.309"],["79668.60","0.207"],["79715.10","1.852"],["79715.20","0.000"],["79754.70","0.268"],["79784.00","0.012"],["79784.60","0.015"],["79784.70","0.000"],["79786.80","0.008"],["79789.80","0.083"],["79792.80","0.021"],["79795.40","0.000"],["79802.00","0.307"],["79859.20","0.259"],["79861.60","0.021"],["79862.10","0.138"],["79878.30","13.918"]],"a":[["79878.40","4.560"],["79883.90","0.238"],["79886.30","0.003"],["79886.40","0.478"],["79887.80","0.004"],["79891.90","0.030"],["79892.40","0.065"],["79895.90","0.001"],["79896.00","2.404"],["79899.50","0.444"],["79899.60","0.283"],["79899.70","0.002"],["79899.90","0.004"],["79902.00","0.207"],["79903.10","0.984"],["80000.60","0.320"],["80040.00","0.118"],["80040.10","2.072"],["80088.00","7.276"],["80088.10","2.257"],["80677.20","9.847"]],"st":1}
{"e":"depthUpdate","E":1788696024099,"T":1788696024098,"s":"BTCUSDT","ps":"BTCUSDT","U":11488689342712,"u":11488689349894,"pu":11488689342664,"b":[["1000.00","24.604"],["29378.30","0.742"],["29778.30","1.358"],["63903.00","0.032"],["71890.40","0.002"],["78516.40","0.125"],["78873.20","11.360"],["78919.80","45.093"],["79079.50","10.589"],["79522.80","0.005"],["79524.80","0.061"],["79667.20","3.056"],["79668.60","0.120"],["79848.40","1.075"],["79857.60","0.048"],["79859.90","0.438"],["79860.60","0.000"],["79863.90","0.202"],["79868.50","0.098"],["79870.20","0.034"],["79875.60","0.040"],["79878.10","0.156"]],"a":[["79883.90","0.162"],["79884.60","0.006"],["79886.30","0.007"],["79886.40","0.519"],["79891.30","0.092"],["79891.60","0.326"],["79891.90","0.026"],["79892.40","0.140"],["79892.80","0.104"],["79894.50","0.082"],["79896.40","0.442"],["79899.50","0.006"],["79899.90","0.003"],["79900.90","2.369"],["79969.70","0.000"],["79990.20","0.001"],["80275.80","0.012"],["80677.20","9.847"],["82194.90","0.388"]],"st":1}
{"e":"depthUpdate","E":1788696024201,"T":1788696024200,"s":"BTCUSDT","ps":"BTCUSDT","U":11488689349896,"u":11488689359084,"pu":11488689349894,"b":[["29378.30","0.560"],["29778.30","1.540"],["63903.00","0.000"],["71890.40","0.002"],["76683.10","0.000"],["78511.50","0.636"],["78720.10","10.821"],["78804.00","4.121"],["79079.50","10.589"],["79667.20","3.057"],["79668.60","0.207"],["79872.50","0.001"],["79874.10","0.376"],["79875.60","0.001"]],"a":[["79884.70","0.077"],["79886.30","0.018"],["79886.40","0.497"],["79892.40","0.082"],["79896.40","0.004"],["79899.70","0.440"],["79956.10","0.036"],["79960.10","0.001"],["79961.70","0.001"],["79962.10","0.020"],["79990.20","0.059"],["80277.80","4.192"],["80677.20","9.849"],["80917.80","1.728"]],"st":1}
{"e":"depthUpdate","E":1788696024303,"T":1788696024302,"s":"BTCUSDT","ps":"BTCUSDT","U":11488689359211,"u":11488689367553,"pu":11488689359084,"b":[["1000.00","24.604"],["29378.30","0.378"],["29778.30","1.722"],["71890.40","0.002"],["76683.10","0.002"],["78873.20","11.145"],["79079.50","10.589"],["79478.90","4.472"],["79522.80","0.000"],["79524.80","0.066"],["79667.20","3.056"],["79668.60","0.187"],["79853.60","0.002"],["79855.30","0.453"],["79862.10","0.134"],["79875.60","0.040"]],"a":[["79878.40","4.150"],["79883.70","0.000"],["79884.60","0.082"],["79884.70","0.001"],["79886.30","0.018"],["79886.40","0.478"],["79892.00","0.029"],["79892.40","0.123"],["80275.80","0.001"],["80677.20","9.847"]],"st":1}
{"e":"depthUpdate","E":1788696024405,"T":1788696024404,"s":"BTCUSDT","ps":"BTCUSDT","U":11488689367613,"u":11488689376892,"pu":11488689367553,"b":[["1000.00","24.604"],["29378.30","0.252"],["29678.30","0.049"],["29778.30","1.799"],["71890.40","0.002"],["76683.10","0.000"],["79079.50","10.589"],["79478.90","4.470"],["79667.20","3.056"],["79668.60","0.207"],["79670.60","0.027"],["79676.50","0.000"],["79699.70","0.037"],["79726.10","0.002"],["79749.40","0.025"],["79822.30","0.003"],["79832.20","0.002"],["79839.50","0.001"],["79841.60","0.060"],["79844.80","0.002"],["79846.30","0.036"],["79846.40","8.158"],["79847.60","2.006"],["79853.60","0.452"],["79854.70","0.005"],["79855.30","0.003"],["79857.70","0.000"],["79858.40","0.008"],["79858.70","0.063"],["79859.10","0.827"],["79859.30","0.000"],["79859.40","0.001"],["79860.00","0.009"],["79860.70","0.075"],["79861.70","0.443"],["79862.00","0.565"],["79862.10","0.138"],["79862.70","0.066"],["79863.60","0.003"],["79864.10","0.006"],["79864.40","0.001"],["79865.00","0.082"],["79866.60","0.037"],["79868.50","0.094"],["79870.20","0.038"],["79875.60","0.040"],["79878.30","12.666"]],"a":[["79880.60","0.145"],["79881.30","0.003"],["79882.40","0.155"],["79883.10","0.003"],["79883.60","0.003"],["79884.00","0.008"],["79884.10","0.176"],["79884.30","0.079"],["79884.50","0.005"],["79884.60","0.006"],["79886.30","0.014"],["79891.00","0.151"],["79891.70","0.041"],["79892.20","0.006"],["79892.30","0.004"],["79892.40","0.112"],["79892.50","1.014"],["79896.00","2.404"],["79897.70","0.463"],["79897.80","0.065"],["79897.90","0.692"],["79898.00","0.004"],["79899.50","0.000"],["79899.60","0.285"],["79899.70","0.002"],["79900.40","0.643"],["79904.00","0.719"],["79905.50","0.450"],["79905.90","0.000"],["79910.40","0.565"],["79934.40","0.003"],["79968.70","0.007"],["79990.20","0.059"],["80094.20","0.009"],["80101.70","0.031"],["80144.10","0.000"],["80151.60","0.037"],["80275.80","0.012"],["80277.80","4.194"],["80677.20","9.847"],["80807.60","1.252"]],"st":1}
{"e":"depthUpdate","E":1788696024507,"T":1788696024505,"s":"BTCUSDT","ps":"BTCUSDT","U":11488689377092,"u":11488689387077,"pu":11488689376892,"b":[["29378.30","0.133"],["29678.30","0.112"],["29778.30","1.855"],["71890.40","0.002"],["78829.30","0.635"],["79079.50","10.589"],["79163.20","0.020"],["79524.80","0.066"],["79783.50","0.125"],["79833.50","0.079"],["79839.40","0.001"],["79841.60","0.000"],["79853.60","0.002"],["79856.30","0.450"],["79859.60","0.000"],["79859.90","0.007"],["79860.60","0.438"],["79861.60","0.025"],["79861.80","0.191"],["79862.00","0.002"],["79862.10","0.134"],["79862.90","0.563"],["79864.20","0.254"],["79866.60","0.033"],["79867.20","0.095"],["79875.60","0.040"],["79878.30","12.668"]],"a":[["79884.30","0.003"],["79884.50","0.001"],["79884.90","0.004"],["79891.60","0.076"],["79892.40","0.321"],["79892.50","0.389"],["79897.70","0.025"],["79897.80","0.503"],["79899.60","0.281"],["79899.70","0.627"],["79899.80","1.553"],["79903.10","0.421"],["79904.20","0.564"],["79990.20","0.175"],["80322.20","0.004"],["80345.60","0.003"],["80590.50","4.217"],["80677.20","9.847"],["81245.50","2.579"]],"st":1}
{"e":"depthUpdate","E":1788696024609,"T":1788696024607,"s":"BTCUSDT","ps":"BTCUSDT","U":11488689387200,"u":11488689394136,"pu":11488689387077,"b":[["1000.00","24.604"],["29378.30","0.021"],["29678.30","0.175"],["29778.30","1.904"],["63902.60","0.000"],["63903.00","0.000"],["71890.40","0.002"],["72329.50","0.256"],["75975.80","0.145"],["76683.10","0.002"],["79079.50","10.589"],["79478.90","4.470"],["79668.60","0.120"],["79754.70","0.270"],["79783.50","0.000"],["79859.20","0.253"],["79859.60","0.002"],["79859.90","0.000"],["79861.20","0.016"],["79862.70","0.062"],["79863.50","0.081"],["79875.60","0.040"],["79878.10","0.194"],["79878.30","13.925"]],"a":[["79885.80","0.000"],["79886.20","0.005"],["79886.90","0.001"],["79887.00","0.081"],["79888.10","0.191"],["79891.20","0.081"],["79891.70","0.038"],["79892.50","0.392"],["79896.00","2.480"],["79897.70","0.463"],["79897.80","0.065"],["79897.90","0.003"],["79899.60","0.283"],["79900.40","0.012"],["79901.00","0.627"],["79901.30","0.006"],["79904.50","0.000"],["79905.20","0.625"],["79905.30","0.028"],["79908.00","0.917"],["79911.90","0.002"],["79916.60","2.101"],["79916.70","9.368"],["79918.70","0.000"],["79948.70","0.292"],["80000.60","0.320"],["80275.80","0.012"],["80277.80","4.149"],["80677.20","9.847"],["80836.90","38.642"],["80972.70","1.981"],["87866.30","0.000"]],"st":1}
{"e":"depthUpdate","E":1788696024711,"T":1788696024710,"s":"BTCUSDT","ps":"BTCUSDT","U":11488689394365,"u":11488689402422,"pu":11488689394136,"b":[["1000.00","24.604"],["29378.30","0.000"],["29678.30","0.336"],["29778.30","1.764"],["71890.40","0.002"],["71927.00","0.036"],["73328.50","0.317"],["76683.10","0.000"],["78384.60","2.756"],["78877.80","0.005"],["79079.50","10.589"],["79668.60","0.207"],["79769.00","0.001"],["79855.10","0.652"],["79856.30","0.000"],["79856.60","0.011"],["79875.60","0.040"]],"a":[["79878.40","4.151"],["79885.70","0.077"],["79888.10","0.217"],["79897.50","0.004"],["79897.60","0.022"],["79897.70","0.025"],["79898.00","0.002"],["79899.60","0.721"],["79900.00","0.006"],["79900.50","0.002"],["79900.90","2.368"],["79901.10","0.005"],["79908.40","0.000"],["79909.50","0.625"],["79990.20","0.175"],["80277.80","4.194"],["80632.40","0.000"],["80677.20","9.847"],["80836.90","39.878"],["82124.10","0.000"]],"st":1}
{"e":"depthUpdate","E":1788696024813,"T":1788696024811,"s":"BTCUSDT","ps":"BTCUSDT","U":11488689402560,"u":11488689410795,"pu":11488689402422,"b":[["29678.30","0.511"],["29778.30","1.589"],["71890.40","0.002"],["71927.00","0.033"],["75884.50","0.269"],["76683.10","0.002"],["78708.10","5.763"],["78992.10","0.000"],["79079.50","10.589"],["79524.80","0.066"],["79668.60","0.207"],["79783.70","0.224"],["79795.40","0.000"],["79804.60","0.014"],["79806.40","1.199"],["79806.70","0.001"],["79822.30","0.001"],["79838.30","0.006"],["79875.60","0.040"]],"a":[["79897.90","0.001"],["79918.40","0.274"],["79932.00","0.004"],["79934.40","0.001"],["79940.30","0.044"],["79968.80","6.126"],["79969.00","0.329"],["79969.20","0.016"],["79990.20","0.175"],["80275.80","0.012"],["80677.20","9.847"]],"st":1}
{"e":"depthUpdate","E":1788696024915,"T":1788696024914,"s":"BTCUSDT","ps":"BTCUSDT","U":11488689411046,"u":11488689418388,"pu":11488689410795,"b":[["1000.00","24.604"],["29678.30","0.693"],["29778.30","1.407"],["71890.40","0.002"],["76683.10","0.000"],["78604.40","0.003"],["78612.40","0.000"],["78614.50","0.003"],["78617.70","0.002"],["79000.00","49.420"],["79079.50","10.589"],["79478.90","3.958"],["79668.60","0.207"],["79715.10","0.001"],["79754.70","0.000"],["79783.50","0.125"],["79804.60","0.000"],["79815.60","0.014"],["79859.80","0.003"],["79861.20","0.642"],["79875.60","0.001"],["79878.30","12.674"]],"a":[["79968.80","6.001"],["79969.70","0.000"],["79990.20","0.175"],["80000.60","0.001"],["80040.10","0.000"],["80277.80","4.070"],["80677.20","9.847"]],"st":1}
{"e":"depthUpdate","E":1788696025017,"T":1788696025015,"s":"BTCUSDT","ps":"BTCUSDT","U":11488689418465,"u":11488689425085,"pu":11488689418388,"b":[["1000.00","24.604"],["29678.30","0.868"],["29778.30","1.232"],["71890.40","0.002"],["79079.50","10.589"],["79478.90","4.460"],["79524.80","0.066"],["79668.60","0.187"],["79715.10","0.977"],["79754.60","2.026"],["79783.50","0.000"],["79798.10","0.000"],["79807.50","0.210"],["79875.60","0.040"]],"a":[["79878.40","4.366"],["79892.40","0.328"],["79990.20","0.168"],["80000.50","0.275"],["80040.10","1.292"],["80088.00","7.395"],["80275.80","0.001"],["80677.20","9.847"],["80910.10","4.815"]],"st":1}
{"e":"depthUpdate","E":1788696025119,"T":1788696025117,"s":"BTCUSDT","ps":"BTCUSDT","U":11488689425186,"u":11488689431981,"pu":11488689425085,"b":[["29678.30","1.050"],["29778.30","1.050"],["71890.40","0.002"],["75884.40","0.008"],["75884.50","0.271"],["76683.10","0.002"],["78704.10","4.497"],["78879.80","12.300"],["79079.50","10.589"],["79668.60","0.120"],["79766.50","0.752"],["79782.40","0.128"],["79809.40","20.825"],["79812.10","0.001"],["79815.60","0.000"],["79824.40","2.563"],["79858.50","0.003"],["79859.40","0.000"],["79862.60","0.001"],["79863.90","0.202"],["79865.80","0.012"],["79875.60","0.040"],["79878.30","12.663"]],"a":[["79878.40","4.561"],["79882.50","0.277"],["79884.50","0.001"],["79891.00","0.152"],["79891.30","0.041"],["79892.50","0.391"],["79892.80","0.104"],["79894.50","0.004"],["79896.00","2.404"],["79911.90","4.643"],["79949.60","0.002"],["79952.30","18.114"],["79990.20","0.110"],["80275.80","0.057"],["80277.80","4.149"],["80597.70","2.625"],["80677.20","9.847"],["81012.70","1.036"],["82120.10","0.751"]],"st":1}
{"e":"depthUpdate","E":1788696025221,"T":1788696025218,"s":"BTCUSDT","ps":"BTCUSDT","U":11488689432053,"u":11488689439039,"pu":11488689431981,"b":[["1000.00","24.604"],["29678.30","1.225"],["29778.30","0.875"],["71890.40","0.002"],["75158.30","0.164"],["75884.40","0.006"],["75884.50","0.271"],["76683.10","0.000"],["78869.20","1.266"],["79079.50","10.589"],["79239.30","4.318"],["79478.90","4.460"],["79524.80","0.060"],["79668.60","0.207"],["79754.60","1.848"],["79858.90","0.001"],["79859.20","0.253"],["79875.60","0.001"],["79878.30","13.914"]],"a":[["79882.50","0.026"],["79892.40","0.321"],["79916.60","0.000"],["79916.70","0.009"],["79949.50","0.991"],["79949.60","18.102"],["79952.20","3.931"],["79952.30","0.014"],["79953.00","0.003"],["79960.00","0.452"],["79990.20","0.156"],["80000.50","0.006"],["80677.20","9.847"],["80892.60","2.330"],["87866.30","0.000"]],"st":1}
{"e":"depthUpdate","E":1788696025323,"T":1788696025322,"s":"BTCUSDT","ps":"BTCUSDT","U":11488689439281,"u":11488689446336,"pu":11488689439039,"b":[["1000.00","24.604"],["29678.30","1.407"],["29778.30","0.693"],["71890.40","0.002"],["76683.10","0.002"],["78869.20","1.899"],["79079.50","10.589"],["79524.80","0.066"],["79667.20","0.000"],["79667.40","0.019"],["79668.60","0.120"],["79715.10","0.001"],["79782.40","0.003"],["79856.40","0.041"],["79857.30","0.626"],["79862.60","0.491"],["79862.70","0.000"],["79863.50","0.143"],["79865.80","0.397"],["79868.70","0.079"],["79870.20","0.288"]],"a":[["79878.40","4.560"],["79884.90","0.000"],["79885.20","0.005"],["79900.00","0.005"],["79900.50","0.003"],["79952.20","0.001"],["79990.20","0.175"],["79990.30","2.604"],["80040.10","0.000"],["80088.00","2.067"],["80275.80","0.012"],["80677.20","9.847"],["80871.40","0.003"]],"st":1}
{"e":"depthUpdate","E":1788696025425,"T":1788696025421,"s":"BTCUSDT","ps":"BTCUSDT","U":11488689446395,"u":11488689452090,"pu":11488689446336,"b":[["29678.30","1.582"],["29778.30","0.518"],["63903.00","0.000"],["71890.40","0.002"],["76683.10","0.000"],["78732.80","0.385"],["78760.00","37.236"],["78953.50","0.000"],["79079.50","10.589"],["79656.60","0.174"],["79667.20","3.057"],["79668.60","0.033"],["79715.10","1.215"],["79754.60","2.102"],["79783.80","0.251"],["79853.60","0.002"],["79855.10","0.202"],["79855.30","0.453"],["79859.20","0.691"],["79860.60","0.000"],["79862.00","0.565"],["79862.90","0.000"]],"a":[["79885.70","0.001"],["79885.80","0.076"],["79891.00","0.151"],["79891.70","0.039"],["79894.40","0.885"],["79896.00","2.404"],["79899.60","0.721"],["79902.10","0.384"],["79903.30","0.566"],["79903.90","0.172"],["79904.20","0.001"],["79905.10","0.451"],["79905.50","0.000"],["79942.30","0.068"],["79990.20","0.175"],["80000.50","0.387"],["80040.10","2.072"],["80088.00","7.386"],["80277.80","4.192"],["80677.20","9.847"]],"st":1}
{"e":"depthUpdate","E":1788696025527,"T":1788696025526,"s":"BTCUSDT","ps":"BTCUSDT","U":11488689452283,"u":11488689459319,"pu":11488689452090,"b":[["1000.00","24.604"],["29578.30","0.007"],["29678.30","1.750"],["29778.30","0.343"],["71890.40","0.002"],["78804.00","3.487"],["79079.50","10.589"],["79478.90","4.472"],["79524.80","0.066"],["79668.60","0.013"],["79754.60","1.848"],["79808.50","0.013"],["79824.50","0.001"],["79859.30","0.007"],["79859.60","0.000"],["79878.30","12.675"]],"a":[["79882.70","0.251"],["79884.60","0.082"],["79897.80","0.503"],["79897.90","0.690"],["79898.00","0.004"],["79899.60","0.281"],["79990.20","0.175"],["80000.50","0.006"],["80275.80","0.001"],["80677.20","9.847"],["80996.70","41.645"]],"st":1}
{"e":"depthUpdate","E":1788696025629,"T":1788696025626,"s":"BTCUSDT","ps":"BTCUSDT","U":11488689459361,"u":11488689465400,"pu":11488689459319,"b":[["29578.30","0.063"],["29678.30","1.813"],["29778.30","0.224"],["63902.60","0.000"],["63903.00","0.000"],["71890.40","0.002"],["75882.60","0.005"],["76683.10","0.002"],["79079.50","10.589"],["79656.60","0.000"],["79668.60","0.207"],["79715.10","0.001"],["79859.60","0.002"],["79873.50","0.029"],["79875.50","0.724"],["79878.10","0.156"]],"a":[["79878.40","4.559"],["79882.60","0.006"],["79884.60","0.006"],["79891.30","0.088"],["79894.50","0.076"],["79897.90","0.692"],["79899.60","0.283"],["79908.00","1.872"],["79990.20","0.175"],["80040.00","0.682"],["80040.10","0.000"],["80086.30","2.160"],["80275.80","0.057"],["80277.80","4.147"],["80662.00","0.013"],["80677.20","9.847"],["80848.00","1.236"],["80881.00","9.543"]],"st":1}
{"e":"depthUpdate","E":1788696025731,"T":1788696025729,"s":"BTCUSDT","ps":"BTCUSDT","U":11488689465579,"u":11488689472321,"pu":11488689465400,"b":[["29578.30","0.126"],["29678.30","1.869"],["29778.30","0.105"],["63903.00","0.000"],["71890.40","0.002"],["72129.70","0.260"],["76683.10","0.000"],["78640.20","6.986"],["78919.80","45.725"],["78956.60","0.026"],["79079.50","10.589"],["79163.50","15.895"],["79524.80","0.045"],["79667.20","2.433"],["79715.10","0.995"],["79747.20","0.145"],["79754.60","2.057"],["79858.50","0.002"],["79859.30","0.000"],["79859.50","0.003"],["79878.30","13.925"]],"a":[["79884.60","0.082"],["79897.70","0.463"],["79897.80","0.065"],["79897.90","0.003"],["79898.00","0.002"],["79899.60","0.283"],["79990.20","0.134"],["80000.50","0.326"],["80040.00","0.118"],["80040.10","1.792"],["80086.30","1.553"],["80088.00","7.069"],["80677.20","9.847"],["80870.10","7.388"]],"st":1}
{"e":"depthUpdate","E":1788696025833,"T":1788696025831,"s":"BTCUSDT","ps":"BTCUSDT","U":11488689472457,"u":11488689479432,"pu":11488689472321,"b":[["1000.00","24.604"],["29578.30","0.203"],["29678.30","1.890"],["29778.30","0.007"],["71890.40","0.002"],["75884.50","0.269"],["76683.10","0.002"],["78512.40","1.097"],["78879.80","12.451"],["79079.50","10.589"],["79478.90","4.472"],["79524.80","0.066"],["79668.60","0.187"],["79735.30","0.001"],["79754.60","1.848"],["79783.70","0.349"],["79783.80","0.126"],["79878.30","13.925"]],"a":[["79882.70","0.000"],["79884.30","0.079"],["79884.60","0.006"],["79886.00","0.027"],["79897.60","0.022"],["79897.70","0.025"],["79897.90","0.001"],["79899.60","0.721"],["79969.70","0.000"],["79990.20","0.175"],["80000.50","0.006"],["80004.60","0.000"],["80275.80","0.057"],["80677.20","9.847"],["80836.90","39.385"]],"st":1}
{"e":"depthUpdate","E":1788696025935,"T":1788696025933,"s":"BTCUSDT","ps":"BTCUSDT","U":11488689479596,"u":11488689491281,"pu":11488689479432,"b":[["29578.30","0.378"],["29678.30","1.722"],["29778.30","0.000"],["71890.40","0.002"],["73128.70","0.317"],["74253.80","0.180"],["78614.50","0.000"],["78617.50","0.003"],["78799.90","5.949"],["79079.50","10.589"],["79159.40","14.109"],["79668.60","0.207"],["79715.10","0.001"],["79734.70","1.878"]],"a":[["79883.50","0.251"],["79884.30","0.003"],["79884.50","0.077"],["79899.60","0.722"],["79900.50","0.002"],["79969.30","0.001"],["79969.40","0.038"],["79970.00","0.178"],["79990.20","0.175"],["80004.10","1.878"],["80040.10","0.000"],["80300.00","23.160"],["80590.60","5.424"],["80677.20","9.847"]],"st":1}
{"e":"depthUpdate","E":1788696026037,"T":1788696026036,"s":"BTCUSDT","ps":"BTCUSDT","U":11488689491442,"u":11488689499611,"pu":11488689491281,"b":[["29578.30","0.553"],["29678.30","1.547"],["63903.00","0.000"],["71890.40","0.002"],["75882.60","0.000"],["76683.10","0.000"],["78879.80","12.666"],["79079.50","10.589"],["79524.80","0.066"],["79668.60","0.100"],["79715.10","1.227"],["79754.60","2.102"],["79806.40","1.197"],["79838.30","0.008"],["79859.20","0.253"],["79860.60","0.438"],["79861.80","0.191"],["79862.00","0.002"],["79862.90","0.567"],["79863.50","0.139"],["79863.90","0.206"],["79864.10","0.006"],["79866.80","0.006"],["79867.20","0.091"],["79878.10","0.196"],["79878.30","12.672"]],"a":[["79882.60","0.005"],["79890.60","0.001"],["79891.70","0.038"],["79892.80","0.108"],["79903.30","0.003"],["79904.10","2.219"],["79907.70","0.000"],["79908.40","0.006"],["79908.70","0.014"],["79918.40","0.274"],["79969.70","0.125"],["79970.00","0.053"],["79990.20","0.175"],["80000.50","0.370"],["80040.10","1.990"],["80275.80","0.001"],["80677.20","9.847"],["80836.90","39.878"]],"st":1}
{"e":"depthUpdate","E":1788696026139,"T":1788696026137,"s":"BTCUSDT","ps":"BTCUSDT","U":11488689499690,"u":11488689507276,"pu":11488689499611,"b":[["1000.00","24.604"],["29578.30","0.735"],["29678.30","1.365"],["63903.00","0.000"],["71890.40","0.002"],["75884.40","0.008"],["76683.10","0.002"],["79079.50","10.589"],["79159.20","0.126"],["79382.20","0.039"],["79478.90","4.472"],["79668.60","0.207"],["79841.70","0.125"],["79858.70","0.064"],["79859.50","0.002"],["79863.90","0.202"],["79866.80","0.002"],["79867.20","0.095"],["79878.30","12.706"]],"a":[["79892.80","0.104"],["79896.60","0.080"],["79899.50","0.438"],["79899.60","0.284"],["79959.90","0.001"],["79969.70","0.000"],["79969.80","0.038"],["79990.20","0.175"],["80275.80","0.057"],["80677.20","9.847"]],"st":1}
{"e":"depthUpdate","E":1788696026241,"T":1788696026240,"s":"BTCUSDT","ps":"BTCUSDT","U":11488689507381,"u":11488689514799,"pu":11488689507276,"b":[["29578.30","0.910"],["29678.30","1.190"],["71890.40","0.002"],["76683.10","0.000"],["78873.20","10.994"],["79079.50","10.589"],["79190.90","3.610"],["79382.20","0.000"],["79524.80","0.021"],["79754.60","1.848"],["79875.60","0.040"],["79878.00","0.001"],["79878.20","0.024"],["79878.30","12.684"]],"a":[["79883.40","0.001"],["79990.20","0.100"],["80000.50","0.006"],["80517.40","3.468"],["80677.20","9.847"],["81056.80","6.828"],["81252.30","1.597"]],"st":1}
{"e":"depthUpdate","E":1788696026343,"T":1788696026341,"s":"BTCUSDT","ps":"BTCUSDT","U":11488689514900,"u":11488689521909,"pu":11488689514799,"b":[["29578.30","1.092"],["29678.30","1.008"],["63903.00","0.002"],["71890.40","0.002"],["71927.00","0.036"],["76683.10","0.002"],["78906.80","0.040"],["79072.90","18.582"],["79079.50","10.589"],["79524.80","0.066"],["79667.20","3.057"],["79667.90","1.909"],["79668.60","0.120"],["79754.60","2.102"],["79783.70","0.224"],["79853.60","0.002"],["79855.30","0.453"],["79859.20","0.691"],["79860.60","0.000"],["79862.00","0.565"],["79862.90","0.004"],["79875.60","0.040"],["79878.30","13.935"]],"a":[["79884.50","0.001"],["79895.90","0.001"],["79899.50","0.000"],["79899.60","0.721"],["79900.50","0.003"],["79902.00","0.207"],["79903.20","2.047"],["79903.90","0.172"],["79904.10","1.656"],["79905.10","0.451"],["79990.20","0.117"],["80000.50","0.370"],["80275.80","0.057"],["80597.30","0.434"],["80677.20","9.847"]],"st":1}
{"e":"depthUpdate","E":1788696026445,"T":1788696026444,"s":"BTCUSDT","ps":"BTCUSDT","U":11488689522012,"u":11488689527759,"pu":11488689521909,"b":[["1000.00","24.604"],["29578.30","1.267"],["29678.30","0.833"],["63903.00","0.000"],["71890.40","0.002"],["78872.00","0.003"],["79079.50","10.591"],["79123.50","8.489"],["79478.90","4.472"],["79524.80","0.060"],["79668.60","0.207"],["79782.20","0.784"],["79875.60","0.001"]],"a":[["79884.70","0.077"],["79967.60","0.001"],["79990.20","0.163"],["80477.50","4.035"],["80517.40","3.716"],["80870.10","7.178"]],"st":1}
{"e":"depthUpdate","E":1788696026547,"T":1788696026545,"s":"BTCUSDT","ps":"BTCUSDT","U":11488689527809,"u":11488689535457,"pu":11488689527759,"b":[["29578.30","1.449"],["29678.30","0.651"],["71890.40","0.002"],["71927.00","0.033"],["76204.00","0.061"],["76683.10","0.000"],["78986.70","0.632"],["79079.50","10.589"],["79478.90","4.470"],["79524.80","0.066"],["79535.20","0.002"],["79559.40","0.003"],["79668.60","0.100"],["79715.10","0.001"],["79754.60","1.848"],["79756.40","0.000"],["79756.50","0.003"],["79814.30","0.228"],["79822.30","0.003"],["79830.30","0.388"],["79835.90","1.723"],["79851.80","0.690"],["79859.60","0.000"],["79871.60","0.602"],["79875.60","0.040"]],"a":[["79878.40","4.557"],["79884.70","0.001"],["79885.80","0.000"],["79886.00","0.001"],["79897.90","0.690"],["79899.60","0.719"],["79926.40","0.345"],["79934.40","0.003"],["79938.60","0.372"],["79990.20","0.175"],["80000.50","0.006"],["80040.10","0.000"],["80174.30","0.001"],["80198.60","0.003"],["80275.80","0.001"],["80277.80","4.149"],["80517.40","3.220"],["80677.20","9.847"],["81052.60","3.465"],["81397.10","0.012"]],"st":1}
{"e":"depthUpdate","E":1788696026649,"T":1788696026648,"s":"BTCUSDT","ps":"BTCUSDT","U":11488689535519,"u":11488689541601,"pu":11488689535457,"b":[["1000.00","24.604"],["29578.30","1.624"],["29678.30","0.476"],["63902.60","0.000"],["63903.00","0.000"],["71890.40","0.002"],["76683.10","0.002"],["77635.20","0.775"],["79079.50","10.589"],["79119.50","4.726"],["79668.60","0.207"],["79715.10","1.232"],["79754.60","2.102"],["79835.90","0.897"],["79851.80","0.001"],["79853.60","0.452"],["79855.30","0.003"],["79859.60","0.002"],["79862.60","0.001"],["79865.80","0.012"],["79871.20","0.105"],["79875.60","0.040"],["79878.30","12.684"]],"a":[["79878.40","4.553"],["79890.60","0.000"],["79891.10","0.001"],["79891.30","0.041"],["79894.50","0.004"],["79896.00","2.404"],["79897.80","0.503"],["79897.90","0.692"],["79898.00","0.004"],["79899.60","0.283"],["79918.30","0.605"],["79949.50","3.600"],["79990.20","0.175"],["80000.50","0.370"],["80040.00","0.670"],["80040.10","1.990"],["80275.80","0.012"],["80277.80","4.194"],["80343.90","0.002"],["80367.90","0.003"],["80677.20","9.847"],["80753.20","6.790"],["81000.90","37.485"]],"st":1}
{"e":"depthUpdate","E":1788696026751,"T":1788696026749,"s":"BTCUSDT","ps":"BTCUSDT","U":11488689541647,"u":11488689547211,"pu":11488689541601,"b":[["1000.00","24.604"],["29478.30","0.021"],["29578.30","1.764"],["29678.30","0.315"],["71890.40","0.002"],["73254.40","0.201"],["76683.10","0.000"],["78672.10","1.039"],["79079.50","10.589"],["79478.90","4.470"],["79524.80","0.066"],["79747.20","0.166"],["79804.00","24.605"],["79804.80","0.117"],["79809.40","0.016"],["79811.20","0.279"],["79811.90","1.553"],["79812.10","0.001"],["79814.30","0.249"],["79815.20","0.947"],["79853.60","0.002"],["79855.60","0.827"],["79858.70","0.063"],["79859.20","0.698"],["79875.60","0.040"]],"a":[["79885.90","0.077"],["79886.20","0.003"],["79990.20","0.175"],["80277.80","4.070"],["80517.40","3.716"],["80677.20","9.847"],["80852.50","3.717"],["80918.20","0.865"]],"st":1}
{"e":"depthUpdate","E":1788696026853,"T":1788696026851,"s":"BTCUSDT","ps":"BTCUSDT","U":11488689547287,"u":11488689552295,"pu":11488689547211,"b":[["29478.30","0.077"],["29578.30","1.827"],["29678.30","0.196"],["63903.00","0.003"],["71890.40","0.002"],["74766.20","0.167"],["76683.10","0.002"],["79079.50","10.590"],["79478.90","4.470"],["79668.60","0.207"],["79804.00","3.456"],["79809.40","0.016"],["79811.20","0.251"],["79812.10","21.150"],["79846.40","0.158"],["79847.60","0.705"],["79859.20","0.253"],["79859.50","0.003"],["79860.60","0.438"],["79861.80","0.191"],["79862.00","0.002"],["79862.90","0.000"],["79863.10","0.564"],["79864.20","0.254"],["79864.30","0.006"],["79875.60","0.040"],["79878.30","13.935"]],"a":[["79897.70","0.463"],["79897.80","0.065"],["79897.90","0.003"],["79899.60","0.283"],["79903.20","1.484"],["79904.20","0.564"],["79905.10","0.001"],["79906.20","0.451"],["79968.30","0.039"],["79969.00","0.329"],["79969.80","0.038"],["79990.20","0.175"],["80275.80","0.012"],["80277.80","4.070"],["80677.20","9.847"],["81392.90","3.312"]],"st":1}
